Workbook

Sheet 汇总
A1: 品线 | B1: 销售额 | C1: 占公司总销售额比例 | D1: 毛利额 | E1: 毛利额占比 | F1: 广告花费 | G1: 广告花费占公司的比例 | H1: 广告费率 | I1: 总计ASIN数 | J1: 负毛利ASIN数 | K1: 负毛利占比 | L1: 毛利率（补充） | M1: 负毛利ASIN销售额占比（补充）
A2: 逆变器 | B2: =SUMIFS(数据_MSKU!$F:$F,数据_MSKU!$A:$A,$A2) -> 3843776.1 | C2: =B2/$B$10 -> 0.1176352 | D2: =SUMIFS(数据_MSKU!$G:$G,数据_MSKU!$A:$A,$A2) -> 319672.05 | E2: =D2/$D$10 -> 0.07105226 | F2: =SUMIFS(数据_MSKU!$H:$H,数据_MSKU!$A:$A,$A2) -> 664904.02 | G2: =F2/$F$10 -> 0.13732756 | H2: =IFERROR(F2/B2,0) -> 0.17298198 | I2: =COUNTIFS(数据_ASIN!$A:$A,$A2) -> 91 | J2: =COUNTIFS(数据_ASIN!$A:$A,$A2,数据_ASIN!$D:$D,"<0") -> 44 | K2: =IFERROR(J2/I2,0) -> 0.48351648 | L2: =IFERROR(D2/B2,0) -> 0.083166147 | M2: =IFERROR(SUMIFS(数据_ASIN!$C:$C,数据_ASIN!$A:$A,$A2,数据_ASIN!$D:$D,"<0")/B2,0) -> 0.3510637
A3: 油泵 | B3: =SUMIFS(数据_MSKU!$F:$F,数据_MSKU!$A:$A,$A3) -> 2397143.9 | C3: =B3/$B$10 -> 0.073362363 | D3: =SUMIFS(数据_MSKU!$G:$G,数据_MSKU!$A:$A,$A3) -> 609510.08 | E3: =D3/$D$10 -> 0.13547343 | F3: =SUMIFS(数据_MSKU!$H:$H,数据_MSKU!$A:$A,$A3) -> 258949.19 | G3: =F3/$F$10 -> 0.053482695 | H3: =IFERROR(F3/B3,0) -> 0.10802405 | I3: =COUNTIFS(数据_ASIN!$A:$A,$A3) -> 28 | J3: =COUNTIFS(数据_ASIN!$A:$A,$A3,数据_ASIN!$D:$D,"<0") -> 5 | K3: =IFERROR(J3/I3,0) -> 0.17857143 | L3: =IFERROR(D3/B3,0) -> 0.25426512 | M3: =IFERROR(SUMIFS(数据_ASIN!$C:$C,数据_ASIN!$A:$A,$A3,数据_ASIN!$D:$D,"<0")/B3,0) -> 0.0051426784
A4: 钉枪 | B4: =SUMIFS(数据_MSKU!$F:$F,数据_MSKU!$A:$A,$A4) -> 1710642.6 | C4: =B4/$B$10 -> 0.05235263 | D4: =SUMIFS(数据_MSKU!$G:$G,数据_MSKU!$A:$A,$A4) -> 201374.76 | E4: =D4/$D$10 -> 0.044758783 | F4: =SUMIFS(数据_MSKU!$H:$H,数据_MSKU!$A:$A,$A4) -> 253472.5 | G4: =F4/$F$10 -> 0.052351554 | H4: =IFERROR(F4/B4,0) -> 0.14817385 | I4: =COUNTIFS(数据_ASIN!$A:$A,$A4) -> 51 | J4: =COUNTIFS(数据_ASIN!$A:$A,$A4,数据_ASIN!$D:$D,"<0") -> 10 | K4: =IFERROR(J4/I4,0) -> 0.19607843 | L4: =IFERROR(D4/B4,0) -> 0.11771878 | M4: =IFERROR(SUMIFS(数据_ASIN!$C:$C,数据_ASIN!$A:$A,$A4,数据_ASIN!$D:$D,"<0")/B4,0) -> 0.048905118
A5: 充气泵 | B5: =SUMIFS(数据_MSKU!$F:$F,数据_MSKU!$A:$A,$A5) -> 3339273.5 | C5: =B5/$B$10 -> 0.10219537 | D5: =SUMIFS(数据_MSKU!$G:$G,数据_MSKU!$A:$A,$A5) -> 433332.62 | E5: =D5/$D$10 -> 0.096315152 | F5: =SUMIFS(数据_MSKU!$H:$H,数据_MSKU!$A:$A,$A5) -> 536394.27 | G5: =F5/$F$10 -> 0.11078548 | H5: =IFERROR(F5/B5,0) -> 0.16063203 | I5: =COUNTIFS(数据_ASIN!$A:$A,$A5) -> 67 | J5: =COUNTIFS(数据_ASIN!$A:$A,$A5,数据_ASIN!$D:$D,"<0") -> 16 | K5: =IFERROR(J5/I5,0) -> 0.23880597 | L5: =IFERROR(D5/B5,0) -> 0.12976853 | M5: =IFERROR(SUMIFS(数据_ASIN!$C:$C,数据_ASIN!$A:$A,$A5,数据_ASIN!$D:$D,"<0")/B5,0) -> 0.042422449
A6: 黄油枪 | B6: =SUMIFS(数据_MSKU!$F:$F,数据_MSKU!$A:$A,$A6) -> 1628745.2 | C6: =B6/$B$10 -> 0.049846237 | D6: =SUMIFS(数据_MSKU!$G:$G,数据_MSKU!$A:$A,$A6) -> 307132.65 | E6: =D6/$D$10 -> 0.068265177 | F6: =SUMIFS(数据_MSKU!$H:$H,数据_MSKU!$A:$A,$A6) -> 264339.98 | G6: =F6/$F$10 -> 0.054596095 | H6: =IFERROR(F6/B6,0) -> 0.1622967 | I6: =COUNTIFS(数据_ASIN!$A:$A,$A6) -> 17 | J6: =COUNTIFS(数据_ASIN!$A:$A,$A6,数据_ASIN!$D:$D,"<0") -> 3 | K6: =IFERROR(J6/I6,0) -> 0.17647059 | L6: =IFERROR(D6/B6,0) -> 0.1885701 | M6: =IFERROR(SUMIFS(数据_ASIN!$C:$C,数据_ASIN!$A:$A,$A6,数据_ASIN!$D:$D,"<0")/B6,0) -> 0.0027836766
A7: 冲击扳手 | B7: =SUMIFS(数据_MSKU!$F:$F,数据_MSKU!$A:$A,$A7) -> 3420029 | C7: =B7/$B$10 -> 0.10466681 | D7: =SUMIFS(数据_MSKU!$G:$G,数据_MSKU!$A:$A,$A7) -> 495165.8 | E7: =D7/$D$10 -> 0.11005857 | F7: =SUMIFS(数据_MSKU!$H:$H,数据_MSKU!$A:$A,$A7) -> 467865.13 | G7: =F7/$F$10 -> 0.096631653 | H7: =IFERROR(F7/B7,0) -> 0.13680151 | I7: =COUNTIFS(数据_ASIN!$A:$A,$A7) -> 103 | J7: =COUNTIFS(数据_ASIN!$A:$A,$A7,数据_ASIN!$D:$D,"<0") -> 21 | K7: =IFERROR(J7/I7,0) -> 0.2038835 | L7: =IFERROR(D7/B7,0) -> 0.1447841 | M7: =IFERROR(SUMIFS(数据_ASIN!$C:$C,数据_ASIN!$A:$A,$A7,数据_ASIN!$D:$D,"<0")/B7,0) -> 0.038528703
A8: 工作灯 | B8: =SUMIFS(数据_MSKU!$F:$F,数据_MSKU!$A:$A,$A8) -> 3088508.1 | C8: =B8/$B$10 -> 0.094520925 | D8: =SUMIFS(数据_MSKU!$G:$G,数据_MSKU!$A:$A,$A8) -> 586483.82 | E8: =D8/$D$10 -> 0.13035547 | F8: =SUMIFS(数据_MSKU!$H:$H,数据_MSKU!$A:$A,$A8) -> 452612.54 | G8: =F8/$F$10 -> 0.093481423 | H8: =IFERROR(F8/B8,0) -> 0.1465473 | I8: =COUNTIFS(数据_ASIN!$A:$A,$A8) -> 132 | J8: =COUNTIFS(数据_ASIN!$A:$A,$A8,数据_ASIN!$D:$D,"<0") -> 29 | K8: =IFERROR(J8/I8,0) -> 0.21969697 | L8: =IFERROR(D8/B8,0) -> 0.18989227 | M8: =IFERROR(SUMIFS(数据_ASIN!$C:$C,数据_ASIN!$A:$A,$A8,数据_ASIN!$D:$D,"<0")/B8,0) -> 0.054736272
A9: 七品线合计 | B9: =SUM(B2:B8) -> 19428118 | C9: =B9/$B$10 -> 0.59457953 | D9: =SUM(D2:D8) -> 2952671.8 | E9: =D9/$D$10 -> 0.65627884 | F9: =SUM(F2:F8) -> 2898537.6 | G9: =F9/$F$10 -> 0.59865646 | H9: =F9/B9 -> 0.14919292 | I9: =SUM(I2:I8) -> 489 | J9: =SUM(J2:J8) -> 128 | K9: =J9/I9 -> 0.26175869 | L9: =D9/B9 -> 0.1519793 | M9: =SUMIFS(数据_ASIN!$C:$C,数据_ASIN!$D:$D,"<0")/B9 -> 0.09740593
A10: 公司合计 | B10: =SUM(数据_MSKU!$F:$F) -> 32675390 | C10: =B10/$B$10 -> 1 | D10: =SUM(数据_MSKU!$G:$G) -> 4499111.6 | E10: =D10/$D$10 -> 1 | F10: =SUM(数据_MSKU!$H:$H) -> 4841737.8 | G10: =F10/$F$10 -> 1 | H10: =F10/B10 -> 0.14817689 | I10: — | J10: — | K10: — | L10: =D10/B10 -> 0.13769114 | M10: —
A12: 口径说明
A13: 1. 数据源：领星「利润报表-MSKU」2026-01-01 ~ 2026-10-24，全部站点，金额 USD（报表已统一折算）。
A14: 2. 销售额 = FBA销售额 + FBM销售额；毛利额 = 报表「毛利润」；广告花费 = SP + SB + SBV + SD 广告花费。
A15: 3. 品线 = 报表「分类」：逆变器=电源逆变器；油泵=锂电油泵；钉枪=木工钉枪（不含铆钉枪）；黄油枪=黄油枪+黄油枪配件；工作灯=灯具（含车库灯、投光灯等全部灯具）。
A16: 4. ASIN 数 = 报表中出现的去重 ASIN（同一 ASIN 多站点/多 MSKU 合并计算）；负毛利 ASIN = 合并后毛利润 < 0；负毛利占比 = 负毛利 ASIN 数 ÷ 总计 ASIN 数。
A17: 5. 公司合计 = 报表全部 MSKU（含七品线以外的其他分类）。
A18: 6. L、M 两列为补充指标，不在原截图中。

Sheet 数据_MSKU
A1: 品线 | B1: 分类 | C1: MSKU | D1: ASIN | E1: 国家 | F1: 销售额 | G1: 毛利润 | H1: 广告花费
A2: 其他 | B2: 防辐射测试仪 | C2: SKU046490001-US-FBA-1 | D2: B08H5GG9T8 | E2: 美国 | F2: 201821.79 | G2: 36994.05 | H2: 24210.3
A3: 逆变器 | B3: 电源逆变器 | C3: SKU070210002-US-FBA-5 | D3: B0CQ4Q6WB9 | E3: 美国 | F3: 356591.96 | G3: -2216.32 | H3: 76353.64
A4: 逆变器 | B4: 电源逆变器 | C4: SKU070210001-US-FBA-8 | D4: B0CQ2MHKJ5 | E4: 美国 | F4: 277036.5 | G4: -17581.57 | H4: 88811.76
A5: 油泵 | B5: 锂电油泵 | C5: RYBZ012D0A01-FBA-US-11 | D5: B0FW9V5S3W | E5: 美国 | F5: 620662.12 | G5: 175251.02 | H5: 66311.97
A6: 逆变器 | B6: 电源逆变器 | C6: SKU070220002-US-FBA-5 | D6: B0CQ4PFGH5 | E6: 美国 | F6: 207771.72 | G6: -14767.27 | H6: 55894.95
A7: 充气泵 | B7: 充气泵 | C7: SKU120760002-us-11-fba | D7: B0CMD3CGRN | E7: 美国 | F7: 295898.91 | G7: 41999.14 | H7: 54911.41
A8: 逆变器 | B8: 电源逆变器 | C8: SKU070220001-US-FBA-8 | D8: B0CQ2JJ51T | E8: 美国 | F8: 202420.18 | G8: -6839.31 | H8: 61734.03
A9: 油泵 | B9: 锂电油泵 | C9: RYBZ081H0A1-FBA-US-11-NEW | D9: B0GLXXSDXD | E9: 美国 | F9: 461635.6 | G9: 117209.85 | H9: 54699.62
A10: 逆变器 | B10: 电源逆变器 | C10: SKU070600001-0-US-FBA-8 | D10: B0DHZSTBSD | E10: 美国 | F10: 240460.51 | G10: 54653.57 | H10: 37357.99
A11: 工作灯 | B11: 灯具 | C11: GZDZ031D0A01-HK8 | D11: B0GJB7M62C | E11: 美国 | F11: 198823.03 | G11: 51231.95 | H11: 26986.75
A12: 其他 | B12: 防辐射测试仪 | C12: SKU046490001-US-FBA-HK3 | D12: B08H5GG9T8 | E12: 美国 | F12: 83467.2 | G12: 12987.51 | H12: 10192.16
A13: 充气泵 | B13: 充气泵 | C13: New-SKU120760001 | D13: B0CMH9MT2X | E13: 美国 | F13: 217681.89 | G13: 28197.34 | H13: 38278.89
... A1055: 充气泵 | B1055: 充气泵 | C1055: SKU121030002-2-US-FBA-8 | D1055: B0DZBKC4M8 | E1055: 美国 | F1055: 5270.21 | G1055: -1054.33 | H1055: 232.49
A1056: 其他 | C1056: amzn.gr.SKU121090002-US-FBA-11-kW8OMj-LN | D1056: B0CTKFKGL9 | E1056: 美国 | F1056: 3835.24 | G1056: 1416.05 | H1056: 145.38
A1057: 逆变器 | B1057: 电源逆变器 | C1057: NBQZ081M0A1-US-FBA-HK8 | D1057: B0CQ2JJ51T | E1057: 美国 | F1057: 2270.4 | G1057: 303.54 | H1057: 403.09
A1058: 充气泵 | B1058: 充气泵 | C1058: SKU121190001-FBA-CA-HK8 | D1058: B0DXCZ7L7C | E1058: 加拿大 | F1058: 2124.55 | G1058: 267.99 | H1058: 444.1
A1059: 其他 | B1059: 激光水平仪 | C1059: SPYZ021D0A01-CA-FBA-HK11 | D1059: B0GCD1BLZJ | E1059: 加拿大 | F1059: 9763.89 | G1059: 568.13 | H1059: 1718.24
A1060: 油泵 | B1060: 锂电油泵 | C1060: RYBZ021T0A2-EU-5-FBA | D1060: B0GS5FYL8N | E1060: 法国 | F1060: 5041.53 | G1060: 1164.27 | H1060: 908.54
A1061: 其他 | B1061: 绿篱机 | C1061: GLLZ011D0A01-FBA-US-5 | D1061: B0GQSZXK24 | E1061: 加拿大 | F1061: 6901.7 | G1061: 1703.69 | H1061: 21.79
A1062: 冲击扳手 | B1062: 冲击扳手 | C1062: SKU121170002-CA-11-FBA | D1062: B0DRVT9JFD | E1062: 加拿大 | F1062: 9085.83 | G1062: 1632.07 | H1062: 416.71
A1063: 其他 | B1063: 角磨机 | C1063: SKU120840002-FBA-13-US | D1063: B0CQC4X3FC | E1063: 美国 | F1063: 3114.46 | G1063: 704.79 | H1063: 189.72
A1064: 其他 | B1064: 金属铁皮剪 | C1064: SKU070840001-FBA-US-HK1 | D1064: B0DJ779CZ4 | E1064: 美国 | F1064: 4721.65 | G1064: 437.25 | H1064: 1061.14
A1065: 其他 | B1065: 铆钉枪 | C1065: SKU070950001-FBA-US-1 | D1065: B0DS7DVCN2 | E1065: 美国 | F1065: 5267.72 | G1065: 1280.43 | H1065: 200.14
A1066: 其他 | B1066: 喷漆枪 | C1066: PQQZ011T0A01-EU-5-FBA | D1066: B0FMRB911D | E1066: 德国 | F1066: 2379.91 | G1066: -1035.02 | H1066: 841.06
A1067: 工作灯 | B1067: 灯具 | C1067: SKU070620001-HK8 | D1067: B0DT6MNSXW | E1067: 美国 | F1067: 5882.26 | G1067: 2640.66 | H1067: 32.06
A1068: 其他 | B1068: 铆钉枪 | C1068: SKU070820002-EU-5-FBA | D1068: B0DK334C46 | E1068: 法国 | F1068: 3738.72 | G1068: 506.42 | H1068: 50.74
... A1259: 其他 | B1259: 修枝剪 | C1259: XZJZ022D0A01-FBA-US-HK1 | D1259: B0GZTMRDG3 | E1259: 美国 | F1259: 3519.56 | G1259: -1397.83 | H1259: 736.16
A1260: 其他 | C1260: SKU06776-FBA-US-HK1 | D1260: B0DSPTVJFB | E1260: 加拿大 | F1260: 2556.14 | G1260: 664.22 | H1260: 188.18
A1261: 其他 | B1261: 往复锯 | C1261: WFJZ021D0A01-US-FBA-HK11 | D1261: B0H1KRWWPB | E1261: 美国 | F1261: 2140.77 | G1261: -544.19 | H1261: 1121.67
A1262: 充气泵 | B1262: 充气泵 | C1262: SKU120920002-FBA-US-HK11 | D1262: B0D2P1SG9D | E1262: 美国 | F1262: 1593.57 | G1262: -466.5 | H1262: 747.17
A1263: 其他 | B1263: 锯片机 | C1263: WYBZ111D0A25-FBA-CA-HK11 | D1263: B0G1MTW6YS | E1263: 加拿大 | F1263: 2027.15 | G1263: 426.22 | H1263: 126.78
A1264: 冲击扳手 | B1264: 冲击扳手 | C1264: SKU121130001 | D1264: B0DZC86C1J | E1264: 美国 | F1264: 1980.69 | G1264: 484.08 | H1264: 0
A1265: 其他 | B1265: 角磨机 | C1265: SKU02708-EU-5-FBA | D1265: B08R9F6ZTL | E1265: 西班牙 | F1265: 371.48 | G1265: 74.47 | H1265: 0
A1266: 其他 | B1266: 微耕机 | C1266: WGJZ011T0A01-US-FBA-5 | D1266: B0GGHHPYSW | E1266: 加拿大 | F1266: 3761.46 | G1266: 681.29 | H1266: 11.19
A1267: 冲击扳手 | B1267: 冲击扳手 | C1267: SKU121060005-FBA-US-11 | D1267: B0FDGD2FM1 | E1267: 美国 | F1267: 6082.2 | G1267: 1786.28 | H1267: 1.36
A1268: 其他 | B1268: 修边机 | C1268: XBSZ041M0A01-FBA-CA-HK1 | D1268: B0GR9149YW | E1268: 加拿大 | F1268: 3816.07 | G1268: 719.02 | H1268: 335.82
A1269: 工作灯 | B1269: 灯具 | C1269: SKU13016-HK8-US | D1269: B0CCXS1RMB | E1269: 美国 | F1269: 1328.58 | G1269: 361.31 | H1269: 9.94
A1270: 其他 | B1270: 曲线锯 | C1270: SKU0701180001-FBA-CA-HK3 | D1270: B0DHKRJ9KN | E1270: 加拿大 | F1270: 2412.1 | G1270: 790.39 | H1270: 84.05
A1271: 其他 | B1271: 锯片机 | C1271: WYBZ091D0A01-UK-5-FBA | D1271: B0FRSBRJ3X | E1271: 英国 | F1271: 1784 | G1271: -921.01 | H1271: 196.1
...

Sheet 数据_ASIN
A1: 品线 | B1: ASIN | C1: 销售额 | D1: 毛利润 | E1: 广告花费
A2: 充气泵 | B2: B0CMD3CGRN | C2: 445143.37 | D2: 62107.84 | E2: 78613.96
A3: 充气泵 | B3: B0CMH9MT2X | C3: 595470.17 | D3: 90877.65 | E3: 89537.52
A4: 充气泵 | B4: B0D2NQMCRK | C4: 86657.45 | D4: 11220.06 | E4: 12022.16
A5: 充气泵 | B5: B0D2NR1Q2W | C5: 253385.62 | D5: 41728.92 | E5: 37259.96
A6: 充气泵 | B6: B0D2P1SG9D | C6: 22954.55 | D6: 2839.25 | E6: 3115.66
A7: 充气泵 | B7: B0D2P2QWQ9 | C7: 131831.12 | D7: 18709.2 | E7: 23162.95
A8: 充气泵 | B8: B0D2Q68LSQ | C8: 70860.54 | D8: 13133.98 | E8: 8715.59
A9: 充气泵 | B9: B0DB23DJXQ | C9: 103705.31 | D9: 20675.61 | E9: 12573.75
A10: 充气泵 | B10: B0DFCKRYNJ | C10: 13281.6 | D10: 3298.66 | E10: 1086.17
A11: 充气泵 | B11: B0DG1QZD98 | C11: 49680.95 | D11: 3041.25 | E11: 2871.12
A12: 充气泵 | B12: B0DHKQQ54W | C12: 72326.63 | D12: 13302.67 | E12: 9669.03
A13: 充气泵 | B13: B0DHKQSZNT | C13: 75625.63 | D13: 4723.57 | E13: 16974.87
... A490: 黄油枪 | B490: B0H9SD231M | C490: 0 | D490: 0 | E490: 0
