Workbook

Sheet SPU监控与预算
A1: 分类 | B1: SPU | C1: 阶段 | D1: 监控标记 | E1: 销售额 | F1: 占公司比例 | G1: 毛利额 | H1: 毛利额占比 | I1: 广告花费 | J1: 广告占公司比例 | K1: 广告费率 | L1: 净毛利率 | M1: 广告前毛利率 | N1: SP | O1: SB | P1: SBV | Q1: SD | R1: 近30天销售额 | S1: 前30天销售额 | T1: 近30天环比 | U1: 可用库存 | V1: 建议广告费率 | W1: 当前月广告(估) | X1: 建议月预算 | Y1: 预算调整 | Z1: 触发原因 | AA1: 建议
A2: 电源逆变器 | B2: 逆变器-200W | C2: 清货 | D2: 维持 | E2: 3002859.9 | F2: =IFERROR(E2/规则参数!$B$8,0) -> 0.091899741 | G2: 279838.85 | H2: =IFERROR(G2/规则参数!$B$9,0) -> 0.06219869 | I2: 531781.26 | J2: =IFERROR(I2/规则参数!$B$10,0) -> 0.10983273 | K2: =IFERROR(I2/E2,0) -> 0.1770916 | L2: =IFERROR(G2/E2,0) -> 0.093190777 | M2: =K2+L2 -> 0.27028237 | N2: 435095.98 | O2: 32595.46 | P2: 24829.02 | Q2: 39260.8 | R2: 210946.21 | S2: 150852.89 | T2: =IFERROR(R2/S2-1,"") -> 0.3983571 | U2: 45966 | V2: 0.15 | W2: =R2*K2 -> 37356.801 | X2: =R2*V2 -> 31641.931 | Y2: =X2-W2 -> -5714.8697 | AA2: 按建议广告费率执行，月度复盘
A3: 充气泵 | B3: 充气泵-手持高配版 | C3: 成熟 | D3: 维持 | E3: 1863043 | F3: =IFERROR(E3/规则参数!$B$8,0) -> 0.057016701 | G3: 270693.47 | H3: =IFERROR(G3/规则参数!$B$9,0) -> 0.060165982 | I3: 286580.89 | J3: =IFERROR(I3/规则参数!$B$10,0) -> 0.059189675 | K3: =IFERROR(I3/E3,0) -> 0.15382409 | L3: =IFERROR(G3/E3,0) -> 0.14529642 | M3: =K3+L3 -> 0.29912051 | N3: 255309.58 | O3: 15385.78 | P3: 6838.55 | Q3: 9046.98 | R3: 169909.81 | S3: 144772.01 | T3: =IFERROR(R3/S3-1,"") -> 0.17363716 | U3: 41299 | V3: 0.1538 | W3: =R3*K3 -> 26136.222 | X3: =R3*V3 -> 26132.129 | Y3: =X3-W3 -> -4.093314 | AA3: 按建议广告费率执行，月度复盘
A4: 冲击扳手 | B4: 冲击扳手-1/2英寸1100N | C4: 成熟 | D4: 维持 | E4: 1212161.6 | F4: =IFERROR(E4/规则参数!$B$8,0) -> 0.037097082 | G4: 116793.55 | H4: =IFERROR(G4/规则参数!$B$9,0) -> 0.025959247 | I4: 185987.22 | J4: =IFERROR(I4/规则参数!$B$10,0) -> 0.038413319 | K4: =IFERROR(I4/E4,0) -> 0.15343434 | L4: =IFERROR(G4/E4,0) -> 0.096351466 | M4: =K4+L4 -> 0.24978581 | N4: 170933.16 | O4: 3891.84 | P4: 6511.8 | Q4: 4650.42 | R4: 95333.91 | S4: 82880.23 | T4: =IFERROR(R4/S4-1,"") -> 0.15026117 | U4: 7071 | V4: 0.1498 | W4: =R4*K4 -> 14627.496 | X4: =R4*V4 -> 14281.02 | Y4: =X4-W4 -> -346.47587 | AA4: 按建议广告费率执行，月度复盘
A5: 黄油枪 | B5: 黄油枪-直柄/手枪两用款 | C5: 成熟 | D5: 维持 | E5: 1035369.9 | F5: =IFERROR(E5/规则参数!$B$8,0) -> 0.031686536 | G5: 195638.66 | H5: =IFERROR(G5/规则参数!$B$9,0) -> 0.043483842 | I5: 180059.88 | J5: =IFERROR(I5/规则参数!$B$10,0) -> 0.037189102 | K5: =IFERROR(I5/E5,0) -> 0.17390874 | L5: =IFERROR(G5/E5,0) -> 0.18895532 | M5: =K5+L5 -> 0.36286406 | N5: 147037.02 | O5: 10697.21 | P5: 16736.13 | Q5: 5589.52 | R5: 57122.68 | S5: 69470.05 | T5: =IFERROR(R5/S5-1,"") -> -0.17773659 | U5: 6125 | V5: 0.1739 | W5: =R5*K5 -> 9934.1333 | X5: =R5*V5 -> 9933.6341 | Y5: =X5-W5 -> -0.49925442 | AA5: 按建议广告费率执行，月度复盘
A6: 灯具 | B6: 工作灯-薄款双开关16珠21W | C6: 成熟 | D6: 维持 | E6: 1105640.7 | F6: =IFERROR(E6/规则参数!$B$8,0) -> 0.033837108 | G6: 204102.62 | H6: =IFERROR(G6/规则参数!$B$9,0) -> 0.045365094 | I6: 172553.43 | J6: =IFERROR(I6/规则参数!$B$10,0) -> 0.035638739 | K6: =IFERROR(I6/E6,0) -> 0.15606646 | L6: =IFERROR(G6/E6,0) -> 0.18460122 | M6: =K6+L6 -> 0.34066768 | N6: 157884.26 | O6: 7752.39 | P6: 6130.52 | Q6: 786.26 | R6: 109488.77 | S6: 95953.42 | T6: =IFERROR(R6/S6-1,"") -> 0.14106167 | U6: 19230 | V6: 0.1561 | W6: =R6*K6 -> 17087.525 | X6: =R6*V6 -> 17091.197 | Y6: =X6-W6 -> 3.6722614 | AA6: 按建议广告费率执行，月度复盘
A7: 冲击扳手 | B7: 冲击扳手-1/2英寸1600N | C7: 成熟 | D7: 维持 | E7: 1162804.6 | F7: =IFERROR(E7/规则参数!$B$8,0) -> 0.035586554 | G7: 186226.9 | H7: =IFERROR(G7/规则参数!$B$9,0) -> 0.041391927 | I7: 140260.28 | J7: =IFERROR(I7/规则参数!$B$10,0) -> 0.028968995 | K7: =IFERROR(I7/E7,0) -> 0.1206224 | L7: =IFERROR(G7/E7,0) -> 0.16015322 | M7: =K7+L7 -> 0.28077563 | N7: 135851.54 | O7: 2007.85 | P7: 2300.17 | Q7: 100.72 | R7: 128875.55 | S7: 92475.09 | T7: =IFERROR(R7/S7-1,"") -> 0.39362449 | U7: 5078 | V7: 0.1206 | W7: =R7*K7 -> 15545.279 | X7: =R7*V7 -> 15542.391 | Y7: =X7-W7 -> -2.8871716 | AA7: 按建议广告费率执行，月度复盘
A8: 吹叶机 | B8: 手持吹叶机-无刷裸机 | C8: 成熟 | D8: 维持 | E8: 763528.92 | F8: =IFERROR(E8/规则参数!$B$8,0) -> 0.023367094 | G8: 122664.21 | H8: =IFERROR(G8/规则参数!$B$9,0) -> 0.027264096 | I8: 105902.97 | J8: =IFERROR(I8/规则参数!$B$10,0) -> 0.021872925 | K8: =IFERROR(I8/E8,0) -> 0.13870198 | L8: =IFERROR(G8/E8,0) -> 0.16065431 | M8: =K8+L8 -> 0.29935628 | N8: 102611.25 | O8: 2031.51 | P8: 869.82 | Q8: 390.39 | R8: 89317.92 | S8: 76713.07 | T8: =IFERROR(R8/S8-1,"") -> 0.16431164 | U8: 18931 | V8: 0.1387 | W8: =R8*K8 -> 12388.572 | X8: =R8*V8 -> 12388.396 | Y8: =X8-W8 -> -0.17649956 | AA8: 按建议广告费率执行，月度复盘
A9: 锂电油泵 | B9: 锂电油泵-感应自停 | C9: 清货 | D9: 观察 | E9: 1053256.3 | F9: =IFERROR(E9/规则参数!$B$8,0) -> 0.032233931 | G9: 291849.57 | H9: =IFERROR(G9/规则参数!$B$9,0) -> 0.064868266 | I9: 102995.78 | J9: =IFERROR(I9/规则参数!$B$10,0) -> 0.021272482 | K9: =IFERROR(I9/E9,0) -> 0.097787956 | L9: =IFERROR(G9/E9,0) -> 0.27709264 | M9: =K9+L9 -> 0.3748806 | N9: 78939.86 | O9: 13896.36 | P9: 9016.67 | Q9: 1142.89 | R9: 43899.05 | S9: 64088.88 | T9: =IFERROR(R9/S9-1,"") -> -0.3150286 | U9: 7721 | V9: 0.0978 | W9: =R9*K9 -> 4292.7984 | X9: =R9*V9 -> 4293.3271 | Y9: =X9-W9 -> 0.52870946 | Z9: 近 30 天销售环比下滑 ≥30% | AA9: 近 30 天销售环比 -32%，广告要跟着降：预算按近 30 天销售重算为 $4,293/月，排查排名、断货、差评或竞品降价
A10: 灯具 | B10: 锂电池工作灯-三头款 | C10: 成熟 | D10: 维持 | E10: 777879.19 | F10: =IFERROR(E10/规则参数!$B$8,0) -> 0.023806271 | G10: 211382.2 | H10: =IFERROR(G10/规则参数!$B$9,0) -> 0.046983097 | I10: 94014.51 | J10: =IFERROR(I10/规则参数!$B$10,0) -> 0.019417514 | K10: =IFERROR(I10/E10,0) -> 0.12086004 | L10: =IFERROR(G10/E10,0) -> 0.27174168 | M10: =K10+L10 -> 0.39260172 | N10: 87200.07 | O10: 3812.34 | P10: 2364.03 | Q10: 638.07 | R10: 253812.31 | S10: 156159.22 | T10: =IFERROR(R10/S10-1,"") -> 0.6253431 | U10: 41287 | V10: 0.1209 | W10: =R10*K10 -> 30675.766 | X10: =R10*V10 -> 30685.908 | Y10: =X10-W10 -> 10.142346 | AA10: 按建议广告费率执行，月度复盘
A11: 高压清洗机 | B11: 无线高压清洗机-无刷三速 | C11: 成熟 | D11: 维持 | E11: 532814.49 | F11: =IFERROR(E11/规则参数!$B$8,0) -> 0.016306293 | G11: 68026.06 | H11: =IFERROR(G11/规则参数!$B$9,0) -> 0.015119887 | I11: 91570.39 | J11: =IFERROR(I11/规则参数!$B$10,0) -> 0.018912711 | K11: =IFERROR(I11/E11,0) -> 0.17186167 | L11: =IFERROR(G11/E11,0) -> 0.12767307 | M11: =K11+L11 -> 0.29953474 | N11: 84458.78 | O11: 658.21 | P11: 4779.56 | Q11: 1673.84 | R11: 12087.9 | S11: 13547.46 | T11: =IFERROR(R11/S11-1,"") -> -0.1077368 | U11: 924 | V11: 0.1719 | W11: =R11*K11 -> 2077.4467 | X11: =R11*V11 -> 2077.91 | Y11: =X11-W11 -> 0.463285 | AA11: 按建议广告费率执行，月度复盘
A12: 充气泵 | B12: 充气泵-卧式高配版 | C12: 成熟 | D12: 维持 | E12: 527114.59 | F12: =IFERROR(E12/规则参数!$B$8,0) -> 0.016131853 | G12: 72088.91 | H12: =IFERROR(G12/规则参数!$B$9,0) -> 0.016022921 | I12: 83401.06 | J12: =IFERROR(I12/规则参数!$B$10,0) -> 0.017225439 | K12: =IFERROR(I12/E12,0) -> 0.15822188 | L12: =IFERROR(G12/E12,0) -> 0.13676136 | M12: =K12+L12 -> 0.29498324 | N12: 77421.4 | O12: 2870.89 | P12: 1404.13 | Q12: 1704.64 | R12: 51721.59 | S12: 47226.65 | T12: =IFERROR(R12/S12-1,"") -> 0.09517804 | U12: 9785 | V12: 0.1582 | W12: =R12*K12 -> 8183.4871 | X12: =R12*V12 -> 8182.3555 | Y12: =X12-W12 -> -1.1315305 | AA12: 按建议广告费率执行，月度复盘
A13: 木工钉枪 | B13: 新款大钉枪-两用无刷 | C13: 清货 | D13: 维持 | E13: 606981.62 | F13: =IFERROR(E13/规则参数!$B$8,0) -> 0.018576109 | G13: 71748.5 | H13: =IFERROR(G13/规则参数!$B$9,0) -> 0.015947259 | I13: 81071.07 | J13: =IFERROR(I13/规则参数!$B$10,0) -> 0.016744209 | K13: =IFERROR(I13/E13,0) -> 0.13356429 | L13: =IFERROR(G13/E13,0) -> 0.11820539 | M13: =K13+L13 -> 0.25176968 | N13: 65735.95 | O13: 3477.27 | P13: 11352.89 | Q13: 504.96 | R13: 53085.98 | S13: 32427.04 | T13: =IFERROR(R13/S13-1,"") -> 0.63708991 | U13: 1543 | V13: 0.1336 | W13: =R13*K13 -> 7090.3913 | X13: =R13*V13 -> 7092.2869 | Y13: =X13-W13 -> 1.8956232 | AA13: 按建议广告费率执行，月度复盘
A14: 锂电油泵 | B14: 锂电油泵-手提5GPM手动款 | C14: 成熟 | D14: 加投 | E14: 763675.52 | F14: =IFERROR(E14/规则参数!$B$8,0) -> 0.023371581 | G14: 201578.02 | H14: =IFERROR(G14/规则参数!$B$9,0) -> 0.044803961 | I14: 80015.46 | J14: =IFERROR(I14/规则参数!$B$10,0) -> 0.016526186 | K14: =IFERROR(I14/E14,0) -> 0.10477678 | L14: =IFERROR(G14/E14,0) -> 0.26395768 | M14: =K14+L14 -> 0.36873446 | N14: 59968.42 | O14: 17493.75 | P14: 1322.59 | Q14: 1230.7 | R14: 32841.45 | S14: 31176.88 | T14: =IFERROR(R14/S14-1,"") -> 0.053391167 | U14: 9283 | V14: 0.1362 | W14: =R14*K14 -> 3441.0213 | X14: =R14*V14 -> 4473.0055 | Y14: =X14-W14 -> 1031.9842 | Z14: 净毛利率 ≥15%、广告费率 ≤12%，有放量空间 | AA14: 利润空间充足：月预算可上调至 $4,473（单月增幅 ≤30%），优先加精准词与 SBV
A15: 锯片机 | B15: 万用宝锯片机-6挡 | C15: 成熟 | D15: 维持 | E15: 507494.1 | F15: =IFERROR(E15/规则参数!$B$8,0) -> 0.015531386 | G15: 38877.74 | H15: =IFERROR(G15/规则参数!$B$9,0) -> 0.0086412037 | I15: 78750.47 | J15: =IFERROR(I15/规则参数!$B$10,0) -> 0.016264918 | K15: =IFERROR(I15/E15,0) -> 0.15517514 | L15: =IFERROR(G15/E15,0) -> 0.076607275 | M15: =K15+L15 -> 0.23178242 | N15: 78617.05 | O15: -171.38 | P15: 302.37 | Q15: 2.43 | R15: 45064.46 | S15: 44682.53 | T15: =IFERROR(R15/S15-1,"") -> 0.008547636 | U15: 6975 | V15: 0.1318 | W15: =R15*K15 -> 6992.8841 | X15: =R15*V15 -> 5939.4958 | Y15: =X15-W15 -> -1053.3882 | AA15: 按建议广告费率执行，月度复盘
A16: 黄油枪 | B16: 黄油枪-无刷三速款 | C16: 成熟 | D16: 维持 | E16: 578968.87 | F16: =IFERROR(E16/规则参数!$B$8,0) -> 0.017718805 | G16: 111875.31 | H16: =IFERROR(G16/规则参数!$B$9,0) -> 0.024866089 | I16: 77924.03 | J16: =IFERROR(I16/规则参数!$B$10,0) -> 0.016094227 | K16: =IFERROR(I16/E16,0) -> 0.13459105 | L16: =IFERROR(G16/E16,0) -> 0.193232 | M16: =K16+L16 -> 0.32782305 | N16: 65339.67 | O16: 3005.09 | P16: 5711.58 | Q16: 3867.69 | R16: 66609.85 | S16: 62333.53 | T16: =IFERROR(R16/S16-1,"") -> 0.068603848 | U16: 4424 | V16: 0.1346 | W16: =R16*K16 -> 8965.0899 | X16: =R16*V16 -> 8965.6858 | Y16: =X16-W16 -> 0.59594309 | AA16: 按建议广告费率执行，月度复盘
A17: 充气泵 | B17: 充气泵-手持低价版 | C17: 成熟 | D17: 维持 | E17: 548585.89 | F17: =IFERROR(E17/规则参数!$B$8,0) -> 0.016788962 | G17: 89283.64 | H17: =IFERROR(G17/规则参数!$B$9,0) -> 0.019844727 | I17: 77263.64 | J17: =IFERROR(I17/规则参数!$B$10,0) -> 0.015957832 | K17: =IFERROR(I17/E17,0) -> 0.14084146 | L17: =IFERROR(G17/E17,0) -> 0.16275234 | M17: =K17+L17 -> 0.30359381 | N17: 67658.81 | O17: 6096.79 | P17: 2107.87 | Q17: 1400.17 | R17: 76791.18 | S17: 48707.94 | T17: =IFERROR(R17/S17-1,"") -> 0.5765639 | U17: 6169 | V17: 0.1408 | W17: =R17*K17 -> 10815.382 | X17: =R17*V17 -> 10812.198 | Y17: =X17-W17 -> -3.1840867 | AA17: 按建议广告费率执行，月度复盘
A18: 灯具 | B18: 工作灯-薄款双开关7寸29W | C18: 成熟 | D18: 维持 | E18: 482241.19 | F18: =IFERROR(E18/规则参数!$B$8,0) -> 0.014758544 | G18: 72155.78 | H18: =IFERROR(G18/规则参数!$B$9,0) -> 0.016037784 | I18: 71200.38 | J18: =IFERROR(I18/规则参数!$B$10,0) -> 0.014705542 | K18: =IFERROR(I18/E18,0) -> 0.14764475 | L18: =IFERROR(G18/E18,0) -> 0.14962592 | M18: =K18+L18 -> 0.29727067 | N18: 60381.21 | O18: 3624.64 | P18: 6637.99 | Q18: 556.54 | R18: 51367.23 | S18: 28856.42 | T18: =IFERROR(R18/S18-1,"") -> 0.78009712 | U18: 2534 | V18: 0.1476 | W18: =R18*K18 -> 7584.1018 | X18: =R18*V18 -> 7581.8031 | Y18: =X18-W18 -> -2.2986902 | AA18: 按建议广告费率执行，月度复盘
A19: 修边机 | B19: 修边机-6件刀头装 | C19: 成熟 | D19: 维持 | E19: 489511.78 | F19: =IFERROR(E19/规则参数!$B$8,0) -> 0.014981054 | G19: 78854.32 | H19: =IFERROR(G19/规则参数!$B$9,0) -> 0.017526642 | I19: 64664.87 | J19: =IFERROR(I19/规则参数!$B$10,0) -> 0.013355715 | K19: =IFERROR(I19/E19,0) -> 0.13210074 | L19: =IFERROR(G19/E19,0) -> 0.16108769 | M19: =K19+L19 -> 0.29318843 | N19: 63368.51 | O19: 195.31 | P19: 952.95 | Q19: 148.1 | R19: 18791.39 | S19: 23866.4 | T19: =IFERROR(R19/S19-1,"") -> -0.21264246 | U19: 1675 | V19: 0.1321 | W19: =R19*K19 -> 2482.3566 | X19: =R19*V19 -> 2482.3426 | Y19: =X19-W19 -> -0.013967943 | AA19: 按建议广告费率执行，月度复盘
A20: 木工钉枪 | B20: 大钉枪-两用款 | C20: 清货 | D20: 维持 | E20: 472895.11 | F20: =IFERROR(E20/规则参数!$B$8,0) -> 0.014472516 | G20: 65366.99 | H20: =IFERROR(G20/规则参数!$B$9,0) -> 0.014528866 | I20: 64382.1 | J20: =IFERROR(I20/规则参数!$B$10,0) -> 0.013297312 | K20: =IFERROR(I20/E20,0) -> 0.13614457 | L20: =IFERROR(G20/E20,0) -> 0.13822725 | M20: =K20+L20 -> 0.27437182 | N20: 59889.73 | O20: 3765.34 | P20: 704.9 | Q20: 22.13 | R20: 33634.63 | S20: 37885.15 | T20: =IFERROR(R20/S20-1,"") -> -0.11219488 | U20: 2029 | V20: 0.1361 | W20: =R20*K20 -> 4579.1721 | X20: =R20*V20 -> 4577.6731 | Y20: =X20-W20 -> -1.4989955 | AA20: 按建议广告费率执行，月度复盘
A21: 风扇 | B21: 风扇-6寸 | C21: 清货 | D21: 观察 | E21: 250330.47 | F21: =IFERROR(E21/规则参数!$B$8,0) -> 0.0076611317 | G21: 16450.35 | H21: =IFERROR(G21/规则参数!$B$9,0) -> 0.0036563552 | I21: 63163.35 | J21: =IFERROR(I21/规则参数!$B$10,0) -> 0.013045595 | K21: =IFERROR(I21/E21,0) -> 0.25231986 | L21: =IFERROR(G21/E21,0) -> 0.065714533 | M21: =K21+L21 -> 0.3180344 | N21: 54757.38 | O21: 1694.65 | P21: 4745.96 | Q21: 1965.36 | R21: 960.1 | S21: 14046.22 | T21: =IFERROR(R21/S21-1,"") -> -0.93164709 | U21: 11 | V21: 0.15 | W21: =R21*K21 -> 242.2523 | X21: =R21*V21 -> 144.015 | Y21: =X21-W21 -> -98.237301 | Z21: 广告费率 ≥20% | AA21: 广告费率 25.2% 偏高（保本 31.8%）：砍高花费 0 单词和 ACOS 超保本的投放，4 周内降到 15.0%；连续 4 周无改善转压缩
A22: 冲击扳手 | B22: 冲击扳手-3/4英寸2200N | C22: 成熟 | D22: 加投 | E22: 532873.06 | F22: =IFERROR(E22/规则参数!$B$8,0) -> 0.016308085 | G22: 124867.05 | H22: =IFERROR(G22/规则参数!$B$9,0) -> 0.027753712 | I22: 55922.91 | J22: =IFERROR(I22/规则参数!$B$10,0) -> 0.011550173 | K22: =IFERROR(I22/E22,0) -> 0.10494603 | L22: =IFERROR(G22/E22,0) -> 0.23432795 | M22: =K22+L22 -> 0.33927397 | N22: 53628.46 | O22: 371.77 | P22: -0.57 | Q22: 1923.25 | R22: 58386.69 | S22: 47492.73 | T22: =IFERROR(R22/S22-1,"") -> 0.22938163 | U22: 1072 | V22: 0.1364 | W22: =R22*K22 -> 6127.4511 | X22: =R22*V22 -> 7963.9445 | Y22: =X22-W22 -> 1836.4934 | Z22: 净毛利率 ≥15%、广告费率 ≤12%，有放量空间 | AA22: 利润空间充足：月预算可上调至 $7,966（单月增幅 ≤30%），优先加精准词与 SBV
A23: 热风枪 | B23: 热风枪-双温基础款5件套 | C23: 成熟 | D23: 维持 | E23: 274351.02 | F23: =IFERROR(E23/规则参数!$B$8,0) -> 0.0083962584 | G23: 37480.64 | H23: =IFERROR(G23/规则参数!$B$9,0) -> 0.0083306757 | I23: 53808 | J23: =IFERROR(I23/规则参数!$B$10,0) -> 0.011113365 | K23: =IFERROR(I23/E23,0) -> 0.1961283 | L23: =IFERROR(G23/E23,0) -> 0.13661564 | M23: =K23+L23 -> 0.33274394 | N23: 45781 | O23: 2207.73 | P23: 4418.98 | Q23: 1400.29 | R23: 27038.79 | S23: 15939.5 | T23: =IFERROR(R23/S23-1,"") -> 0.69633866 | U23: 2457 | V23: 0.18 | W23: =R23*K23 -> 5303.072 | X23: =R23*V23 -> 4866.9822 | Y23: =X23-W23 -> -436.0898 | AA23: 按建议广告费率执行，月度复盘
A24: 修枝剪 | B24: 修枝剪-数显3.0cm | C24: 清货 | D24: 加投 | E24: 449731.87 | F24: =IFERROR(E24/规则参数!$B$8,0) -> 0.013763627 | G24: 69979.54 | H24: =IFERROR(G24/规则参数!$B$9,0) -> 0.01555408 | I24: 50385.73 | J24: =IFERROR(I24/规则参数!$B$10,0) -> 0.010406538 | K24: =IFERROR(I24/E24,0) -> 0.11203504 | L24: =IFERROR(G24/E24,0) -> 0.1556028 | M24: =K24+L24 -> 0.26763785 | N24: 48072.72 | O24: -11.55 | P24: 919.62 | Q24: 1404.94 | R24: 38992.07 | S24: 39009.02 | T24: =IFERROR(R24/S24-1,"") -> -0.00043451489 | U24: 2715 | V24: 0.1456 | W24: =R24*K24 -> 4368.4783 | X24: =R24*V24 -> 5677.2454 | Y24: =X24-W24 -> 1308.7671 | Z24: 净毛利率 ≥15%、广告费率 ≤12%，有放量空间 | AA24: 利润空间充足：月预算可上调至 $5,679（单月增幅 ≤30%），优先加精准词与 SBV
A25: 圆锯 | B25: 电圆锯-7.25英寸新款 | C25: 清货 | D25: 维持 | E25: 283652.57 | F25: =IFERROR(E25/规则参数!$B$8,0) -> 0.0086809237 | G25: 39696.23 | H25: =IFERROR(G25/规则参数!$B$9,0) -> 0.0088231263 | I25: 46772.97 | J25: =IFERROR(I25/规则参数!$B$10,0) -> 0.0096603682 | K25: =IFERROR(I25/E25,0) -> 0.16489528 | L25: =IFERROR(G25/E25,0) -> 0.13994666 | M25: =K25+L25 -> 0.30484194 | N25: 44440.76 | O25: 412.59 | P25: 1905.14 | Q25: 14.48 | R25: 32921.92 | S25: 25838.31 | T25: =IFERROR(R25/S25-1,"") -> 0.27415144 | U25: 740 | V25: 0.15 | W25: =R25*K25 -> 5428.6692 | X25: =R25*V25 -> 4938.288 | Y25: =X25-W25 -> -490.38122 | AA25: 按建议广告费率执行，月度复盘
A26: 冲击起子 | B26: 冲击起子-280N | C26: 成熟 | D26: 观察 | E26: 148892.48 | F26: =IFERROR(E26/规则参数!$B$8,0) -> 0.0045567162 | G26: 18287.22 | H26: =IFERROR(G26/规则参数!$B$9,0) -> 0.0040646291 | I26: 44966.8 | J26: =IFERROR(I26/规则参数!$B$10,0) -> 0.0092873265 | K26: =IFERROR(I26/E26,0) -> 0.30200854 | L26: =IFERROR(G26/E26,0) -> 0.12282165 | M26: =K26+L26 -> 0.42483019 | N26: 44741.93 | O26: -75.96 | P26: -7.28 | Q26: 308.11 | R26: 15241.75 | S26: 13136.66 | T26: =IFERROR(R26/S26-1,"") -> 0.16024545 | U26: 793 | V26: 0.18 | W26: =R26*K26 -> 4603.1386 | X26: =R26*V26 -> 2743.515 | Y26: =X26-W26 -> -1859.6236 | Z26: 广告费率 ≥20% | AA26: 广告费率 30.2% 偏高（保本 42.5%）：砍高花费 0 单词和 ACOS 超保本的投放，4 周内降到 18.0%；连续 4 周无改善转压缩
A27: 割草机 | B27: 打草机-无刷800W | C27: 清货 | D27: 止损 | E27: 344145.18 | F27: =IFERROR(E27/规则参数!$B$8,0) -> 0.010532244 | G27: -36953.05 | H27: =IFERROR(G27/规则参数!$B$9,0) -> -0.0082134103 | I27: 44617.11 | J27: =IFERROR(I27/规则参数!$B$10,0) -> 0.0092151024 | K27: =IFERROR(I27/E27,0) -> 0.12964619 | L27: =IFERROR(G27/E27,0) -> -0.10737634 | M27: =K27+L27 -> 0.022269846 | N27: 40189.33 | O27: 2956.73 | P27: 1031.15 | Q27: 439.9 | R27: 15546.79 | S27: 37843.79 | T27: =IFERROR(R27/S27-1,"") -> -0.58918517 | U27: 1362 | V27: 0 | W27: =R27*K27 -> 2015.582 | X27: =R27*V27 -> 0 | Y27: =X27-W27 -> -2015.582 | Z27: 广告后毛利为负，广告费率 > 广告前毛利率 | AA27: 广告费率 13.0% 已超过广告前毛利率 2.2%：先停泛词/自动广告，只留品牌词与高转化精准词；同步复核定价与采购成本，2 周内毛利转正再恢复
A28: 喷雾器 | B28: 电动喷雾器-16L | C28: 成熟 | D28: 观察 | E28: 267894.4 | F28: =IFERROR(E28/规则参数!$B$8,0) -> 0.0081986595 | G28: 50441.16 | H28: =IFERROR(G28/规则参数!$B$9,0) -> 0.01121136 | I28: 44150.66 | J28: =IFERROR(I28/规则参数!$B$10,0) -> 0.009118763 | K28: =IFERROR(I28/E28,0) -> 0.16480621 | L28: =IFERROR(G28/E28,0) -> 0.18828747 | M28: =K28+L28 -> 0.35309368 | N28: 43214.98 | O28: 627.48 | P28: 308.2 | Q28: 0 | R28: 8225.49 | S28: 17942.28 | T28: =IFERROR(R28/S28-1,"") -> -0.54155826 | U28: 385 | V28: 0.1648 | W28: =R28*K28 -> 1355.6118 | X28: =R28*V28 -> 1355.5608 | Y28: =X28-W28 -> -0.051057442 | Z28: 近 30 天销售环比下滑 ≥30% | AA28: 近 30 天销售环比 -54%，广告要跟着降：预算按近 30 天销售重算为 $1,356/月，排查排名、断货、差评或竞品降价
A29: 热风枪 | B29: 热风枪-双温数显款5件套 | C29: 成熟 | D29: 维持 | E29: 301359.11 | F29: =IFERROR(E29/规则参数!$B$8,0) -> 0.0092228159 | G29: 59375.34 | H29: =IFERROR(G29/规则参数!$B$9,0) -> 0.013197125 | I29: 42076.55 | J29: =IFERROR(I29/规则参数!$B$10,0) -> 0.0086903817 | K29: =IFERROR(I29/E29,0) -> 0.13962262 | L29: =IFERROR(G29/E29,0) -> 0.1970252 | M29: =K29+L29 -> 0.33664783 | N29: 35737.81 | O29: 1343.09 | P29: 3751.72 | Q29: 1243.93 | R29: 30127.89 | S29: 24648.5 | T29: =IFERROR(R29/S29-1,"") -> 0.22230115 | U29: 2838 | V29: 0.1396 | W29: =R29*K29 -> 4206.5351 | X29: =R29*V29 -> 4205.8534 | Y29: =X29-W29 -> -0.68164293 | AA29: 按建议广告费率执行，月度复盘
A30: 微耕机 | B30: 微耕机-四折叠基础款 | C30: 成熟 | D30: 观察 | E30: 332642.57 | F30: =IFERROR(E30/规则参数!$B$8,0) -> 0.010180217 | G30: 37891.96 | H30: =IFERROR(G30/规则参数!$B$9,0) -> 0.0084220982 | I30: 39351.48 | J30: =IFERROR(I30/规则参数!$B$10,0) -> 0.0081275528 | K30: =IFERROR(I30/E30,0) -> 0.11829959 | L30: =IFERROR(G30/E30,0) -> 0.11391194 | M30: =K30+L30 -> 0.23221153 | N30: 33661.69 | O30: 3754.3 | P30: 1824.18 | Q30: 111.31 | R30: 7102.88 | S30: 11112.35 | T30: =IFERROR(R30/S30-1,"") -> -0.36081207 | U30: 162 | V30: 0.1183 | W30: =R30*K30 -> 840.2678 | X30: =R30*V30 -> 840.2707 | Y30: =X30-W30 -> 0.0029046549 | Z30: 近 30 天销售环比下滑 ≥30% | AA30: 近 30 天销售环比 -36%，广告要跟着降：预算按近 30 天销售重算为 $840/月，排查排名、断货、差评或竞品降价
A31: 锂电油泵 | B31: 锂电油泵-手提款-两用自动+手动5.0GPM | C31: 新品期 | D31: 观察 | E31: 260873.73 | F31: =IFERROR(E31/规则参数!$B$8,0) -> 0.0079837984 | G31: 43558.11 | H31: =IFERROR(G31/规则参数!$B$9,0) -> 0.0096814913 | I31: 38275.94 | J31: =IFERROR(I31/规则参数!$B$10,0) -> 0.0079054136 | K31: =IFERROR(I31/E31,0) -> 0.14672209 | L31: =IFERROR(G31/E31,0) -> 0.16697009 | M31: =K31+L31 -> 0.31369218 | N31: 27631.07 | O31: 6257.2 | P31: 2356.49 | Q31: 2031.18 | R31: 49285.26 | S31: 78687.53 | T31: =IFERROR(R31/S31-1,"") -> -0.37365857 | U31: 1926 | V31: 0.1467 | W31: =R31*K31 -> 7231.2366 | X31: =R31*V31 -> 7230.1476 | Y31: =X31-W31 -> -1.0889208 | Z31: 近 30 天销售环比下滑 ≥30% | AA31: 近 30 天销售环比 -37%，广告要跟着降：预算按近 30 天销售重算为 $7,231/月，排查排名、断货、差评或竞品降价
A32: 冲击电钻 | B32: 锂电钻-13mm 90N.m | C32: 成熟 | D32: 维持 | E32: 243673.24 | F32: =IFERROR(E32/规则参数!$B$8,0) -> 0.0074573934 | G32: 22373.83 | H32: =IFERROR(G32/规则参数!$B$9,0) -> 0.004972944 | I32: 36000.66 | J32: =IFERROR(I32/规则参数!$B$10,0) -> 0.0074354831 | K32: =IFERROR(I32/E32,0) -> 0.14774154 | L32: =IFERROR(G32/E32,0) -> 0.091818987 | M32: =K32+L32 -> 0.23956053 | N32: 35815.09 | O32: 17.89 | P32: 0.73 | Q32: 166.95 | R32: 43261 | S32: 40914.61 | T32: =IFERROR(R32/S32-1,"") -> 0.057348463 | U32: 3329 | V32: 0.1396 | W32: =R32*K32 -> 6391.4468 | X32: =R32*V32 -> 6039.2356 | Y32: =X32-W32 -> -352.21121 | AA32: 按建议广告费率执行，月度复盘
A33: 防辐射测试仪 | B33: 电磁辐射检测仪-手持款 | C33: 成熟 | D33: 维持 | E33: 297895.57 | F33: =IFERROR(E33/规则参数!$B$8,0) -> 0.0091168175 | G33: 53505.46 | H33: =IFERROR(G33/规则参数!$B$9,0) -> 0.01189245 | I33: 35945 | J33: =IFERROR(I33/规则参数!$B$10,0) -> 0.0074239873 | K33: =IFERROR(I33/E33,0) -> 0.12066309 | L33: =IFERROR(G33/E33,0) -> 0.17961147 | M33: =K33+L33 -> 0.30027456 | N33: 35945 | O33: 0 | P33: 0 | Q33: 0 | R33: 51265.33 | S33: 22961.83 | T33: =IFERROR(R33/S33-1,"") -> 1.2326326 | U33: 4813 | V33: 0.1207 | W33: =R33*K33 -> 6185.8331 | X33: =R33*V33 -> 6187.7253 | Y33: =X33-W33 -> 1.8921988 | AA33: 按建议广告费率执行，月度复盘
A34: 充气泵 | B34: 充气泵-卧式双供电26气缸 | C34: 新品期 | D34: 观察 | E34: 168703.85 | F34: =IFERROR(E34/规则参数!$B$8,0) -> 0.0051630248 | G34: 4916.72 | H34: =IFERROR(G34/规则参数!$B$9,0) -> 0.0010928202 | I34: 35581.83 | J34: =IFERROR(I34/规则参数!$B$10,0) -> 0.0073489791 | K34: =IFERROR(I34/E34,0) -> 0.21091297 | L34: =IFERROR(G34/E34,0) -> 0.029144089 | M34: =K34+L34 -> 0.24005706 | N34: 35234.85 | O34: 270.28 | P34: 76.7 | Q34: 0 | R34: 42183.49 | S34: 26869.06 | T34: =IFERROR(R34/S34-1,"") -> 0.56996523 | U34: 5636 | V34: 0.2109 | W34: =R34*K34 -> 8897.0451 | X34: =R34*V34 -> 8896.498 | Y34: =X34-W34 -> -0.54710638 | Z34: 新品期：净毛利 <5%，处于保本投放容忍期（≤90 天） | AA34: 新品保本期：广告费率不超过 21.1%（保本 24.0%）；90 天内净毛利未到 5% 转入压缩
A35: 刨木机 | B35: 刨木机-普通款 | C35: 成熟 | D35: 维持 | E35: 271360.02 | F35: =IFERROR(E35/规则参数!$B$8,0) -> 0.0083047216 | G35: 40097.51 | H35: =IFERROR(G35/规则参数!$B$9,0) -> 0.0089123172 | I35: 35422.04 | J35: =IFERROR(I35/规则参数!$B$10,0) -> 0.0073159765 | K35: =IFERROR(I35/E35,0) -> 0.13053522 | L35: =IFERROR(G35/E35,0) -> 0.14776499 | M35: =K35+L35 -> 0.27830021 | N35: 28331.72 | O35: 1692.01 | P35: 4537.09 | Q35: 861.22 | R35: 31161.98 | S35: 20224.36 | T35: =IFERROR(R35/S35-1,"") -> 0.54081415 | U35: 1286 | V35: 0.1305 | W35: =R35*K35 -> 4067.7359 | X35: =R35*V35 -> 4066.6384 | Y35: =X35-W35 -> -1.0975353 | AA35: 按建议广告费率执行，月度复盘
A36: 电源逆变器 | B36: 逆变器-550W | C36: 成熟 | D36: 加投 | E36: 393243.09 | F36: =IFERROR(E36/规则参数!$B$8,0) -> 0.01203484 | G36: 69042.97 | H36: =IFERROR(G36/规则参数!$B$9,0) -> 0.015345912 | I36: 35350.94 | J36: =IFERROR(I36/规则参数!$B$10,0) -> 0.0073012917 | K36: =IFERROR(I36/E36,0) -> 0.089895896 | L36: =IFERROR(G36/E36,0) -> 0.17557326 | M36: =K36+L36 -> 0.26546915 | N36: 31798.61 | O36: 1748.2 | P36: 194.48 | Q36: 1609.65 | R36: 33005.06 | S36: 26294.33 | T36: =IFERROR(R36/S36-1,"") -> 0.25521586 | U36: 955 | V36: 0.1169 | W36: =R36*K36 -> 2967.0194 | X36: =R36*V36 -> 3858.2915 | Y36: =X36-W36 -> 891.27207 | Z36: 净毛利率 ≥15%、广告费率 ≤12%，有放量空间 | AA36: 利润空间充足：月预算可上调至 $3,857（单月增幅 ≤30%），优先加精准词与 SBV
A37: 木工钉枪 | B37: 钉枪-小型两用 | C37: 清货 | D37: 观察 | E37: 181025.33 | F37: =IFERROR(E37/规则参数!$B$8,0) -> 0.0055401122 | G37: 28205.98 | H37: =IFERROR(G37/规则参数!$B$9,0) -> 0.0062692332 | I37: 34046.42 | J37: =IFERROR(I37/规则参数!$B$10,0) -> 0.0070318595 | K37: =IFERROR(I37/E37,0) -> 0.18807545 | L37: =IFERROR(G37/E37,0) -> 0.15581234 | M37: =K37+L37 -> 0.34388779 | N37: 32417.86 | O37: 1155.84 | P37: 472.72 | Q37: 0 | R37: 8492.32 | S37: 22702.27 | T37: =IFERROR(R37/S37-1,"") -> -0.62592639 | U37: 578 | V37: 0.15 | W37: =R37*K37 -> 1597.1969 | X37: =R37*V37 -> 1273.848 | Y37: =X37-W37 -> -323.34889 | Z37: 近 30 天销售环比下滑 ≥30% | AA37: 近 30 天销售环比 -63%，广告要跟着降：预算按近 30 天销售重算为 $1,274/月，排查排名、断货、差评或竞品降价
A38: 冲击扳手 | B38: 冲击扳手-3/8英寸340N | C38: 成熟 | D38: 观察 | E38: 145227.14 | F38: =IFERROR(E38/规则参数!$B$8,0) -> 0.0044445418 | G38: 33323.94 | H38: =IFERROR(G38/规则参数!$B$9,0) -> 0.0074067822 | I38: 32184.92 | J38: =IFERROR(I38/规则参数!$B$10,0) -> 0.0066473901 | K38: =IFERROR(I38/E38,0) -> 0.22161781 | L38: =IFERROR(G38/E38,0) -> 0.22946083 | M38: =K38+L38 -> 0.45107863 | N38: 32214.39 | O38: -76.64 | P38: 47.17 | Q38: 0 | R38: 13161.18 | S38: 13161.5 | T38: =IFERROR(R38/S38-1,"") -> -2.4313338e-05 | U38: 697 | V38: 0.18 | W38: =R38*K38 -> 2916.7518 | X38: =R38*V38 -> 2369.0124 | Y38: =X38-W38 -> -547.73942 | Z38: 广告费率 ≥20% | AA38: 广告费率 22.2% 偏高（保本 45.1%）：砍高花费 0 单词和 ACOS 超保本的投放，4 周内降到 18.0%；连续 4 周无改善转压缩
A39: 电源逆变器 | B39: 逆变器-350W PD20W | C39: 清货 | D39: 止损 | E39: 115886.94 | F39: =IFERROR(E39/规则参数!$B$8,0) -> 0.0035466122 | G39: -13300.19 | H39: =IFERROR(G39/规则参数!$B$9,0) -> -0.0029561814 | I39: 30462.31 | J39: =IFERROR(I39/规则参数!$B$10,0) -> 0.0062916067 | K39: =IFERROR(I39/E39,0) -> 0.26286232 | L39: =IFERROR(G39/E39,0) -> -0.11476867 | M39: =K39+L39 -> 0.14809365 | N39: 28196.77 | O39: 1860.54 | P39: 138.7 | Q39: 266.3 | R39: 3876.14 | S39: 3811.64 | T39: =IFERROR(R39/S39-1,"") -> 0.01692185 | U39: 499 | V39: 0.0981 | W39: =R39*K39 -> 1018.8912 | X39: =R39*V39 -> 380.24933 | Y39: =X39-W39 -> -638.64182 | Z39: 广告后毛利为负，广告费率 > 广告前毛利率 | AA39: 广告费率 26.3% 已超过广告前毛利率 14.8%：先停泛词/自动广告，只留品牌词与高转化精准词；同步复核定价与采购成本，2 周内毛利转正再恢复
A40: 吹尘枪 | B40: 吹尘枪-5个喷嘴+2条软管 | C40: 成熟 | D40: 维持 | E40: 241434.02 | F40: =IFERROR(E40/规则参数!$B$8,0) -> 0.0073888641 | G40: 30406.61 | H40: =IFERROR(G40/规则参数!$B$9,0) -> 0.0067583586 | I40: 29105.81 | J40: =IFERROR(I40/规则参数!$B$10,0) -> 0.0060114387 | K40: =IFERROR(I40/E40,0) -> 0.12055389 | L40: =IFERROR(G40/E40,0) -> 0.1259417 | M40: =K40+L40 -> 0.24649559 | N40: 28752.97 | O40: 39.74 | P40: 102.81 | Q40: 210.29 | R40: 17238.51 | S40: 16238.08 | T40: =IFERROR(R40/S40-1,"") -> 0.061610116 | U40: 6873 | V40: 0.1206 | W40: =R40*K40 -> 2078.1694 | X40: =R40*V40 -> 2078.9643 | Y40: =X40-W40 -> 0.79488835 | AA40: 按建议广告费率执行，月度复盘
...

Sheet 分类汇总
A1: 品线（分类） | B1: 广告状态 | C1: 状态依据 | D1: 销售额 | E1: 占公司比例 | F1: 毛利额 | G1: 毛利额占比 | H1: 广告花费 | I1: 广告占公司比例 | J1: 广告费率 | K1: 净毛利率 | L1: SPU数 | M1: 当前月广告(估) | N1: 建议月预算
A2: 电源逆变器 | B2: 观察 | C2: 广告费率 17.3% ≥17% | D2: =SUMIFS(SPU监控与预算!$E:$E,SPU监控与预算!$A:$A,$A2) -> 3843776.1 | E2: =D2/规则参数!$B$8 -> 0.1176352 | F2: =SUMIFS(SPU监控与预算!$G:$G,SPU监控与预算!$A:$A,$A2) -> 319672.05 | G2: =F2/规则参数!$B$9 -> 0.07105226 | H2: =SUMIFS(SPU监控与预算!$I:$I,SPU监控与预算!$A:$A,$A2) -> 664904.02 | I2: =H2/规则参数!$B$10 -> 0.13732756 | J2: =IFERROR(H2/D2,0) -> 0.17298198 | K2: =IFERROR(F2/D2,0) -> 0.083166147 | L2: =COUNTIFS(SPU监控与预算!$A:$A,$A2) -> 8 | M2: =SUMIFS(SPU监控与预算!$W:$W,SPU监控与预算!$A:$A,$A2) -> 46907.596 | N2: =SUMIFS(SPU监控与预算!$X:$X,SPU监控与预算!$A:$A,$A2) -> 38639.006
A3: 充气泵 | B3: 维稳 | C3: 净毛利率 13.0%、广告费率 16.1%，在合理区间 | D3: =SUMIFS(SPU监控与预算!$E:$E,SPU监控与预算!$A:$A,$A3) -> 3339273.5 | E3: =D3/规则参数!$B$8 -> 0.10219537 | F3: =SUMIFS(SPU监控与预算!$G:$G,SPU监控与预算!$A:$A,$A3) -> 433332.62 | G3: =F3/规则参数!$B$9 -> 0.096315152 | H3: =SUMIFS(SPU监控与预算!$I:$I,SPU监控与预算!$A:$A,$A3) -> 536394.27 | I3: =H3/规则参数!$B$10 -> 0.11078548 | J3: =IFERROR(H3/D3,0) -> 0.16063203 | K3: =IFERROR(F3/D3,0) -> 0.12976853 | L3: =COUNTIFS(SPU监控与预算!$A:$A,$A3) -> 7 | M3: =SUMIFS(SPU监控与预算!$W:$W,SPU监控与预算!$A:$A,$A3) -> 62233.575 | N3: =SUMIFS(SPU监控与预算!$X:$X,SPU监控与预算!$A:$A,$A3) -> 59989.634
A4: 冲击扳手 | B4: 维稳 | C4: 净毛利率 14.5%、广告费率 13.7%，在合理区间 | D4: =SUMIFS(SPU监控与预算!$E:$E,SPU监控与预算!$A:$A,$A4) -> 3420029 | E4: =D4/规则参数!$B$8 -> 0.10466681 | F4: =SUMIFS(SPU监控与预算!$G:$G,SPU监控与预算!$A:$A,$A4) -> 495175.4 | G4: =F4/规则参数!$B$9 -> 0.11006071 | H4: =SUMIFS(SPU监控与预算!$I:$I,SPU监控与预算!$A:$A,$A4) -> 467865.13 | I4: =H4/规则参数!$B$10 -> 0.096631653 | J4: =IFERROR(H4/D4,0) -> 0.13680151 | K4: =IFERROR(F4/D4,0) -> 0.1447869 | L4: =COUNTIFS(SPU监控与预算!$A:$A,$A4) -> 10 | M4: =SUMIFS(SPU监控与预算!$W:$W,SPU监控与预算!$A:$A,$A4) -> 47876.77 | N4: =SUMIFS(SPU监控与预算!$X:$X,SPU监控与预算!$A:$A,$A4) -> 48329.874
A5: 灯具 | B5: 维稳 | C5: 净毛利率 19.0%、广告费率 14.7%，在合理区间 | D5: =SUMIFS(SPU监控与预算!$E:$E,SPU监控与预算!$A:$A,$A5) -> 3088508.1 | E5: =D5/规则参数!$B$8 -> 0.094520925 | F5: =SUMIFS(SPU监控与预算!$G:$G,SPU监控与预算!$A:$A,$A5) -> 586491.97 | G5: =F5/规则参数!$B$9 -> 0.13035728 | H5: =SUMIFS(SPU监控与预算!$I:$I,SPU监控与预算!$A:$A,$A5) -> 452612.54 | I5: =H5/规则参数!$B$10 -> 0.093481423 | J5: =IFERROR(H5/D5,0) -> 0.1465473 | K5: =IFERROR(F5/D5,0) -> 0.18989491 | L5: =COUNTIFS(SPU监控与预算!$A:$A,$A5) -> 38 | M5: =SUMIFS(SPU监控与预算!$W:$W,SPU监控与预算!$A:$A,$A5) -> 79835.446 | N5: =SUMIFS(SPU监控与预算!$X:$X,SPU监控与预算!$A:$A,$A5) -> 73515.557
A6: 锂电油泵 | B6: 维稳 | C6: 利润空间足（净毛利率 25.4%、广告费率 10.8%），但近 30 天销售环比 -16%，暂不加投 | D6: =SUMIFS(SPU监控与预算!$E:$E,SPU监控与预算!$A:$A,$A6) -> 2397143.9 | E6: =D6/规则参数!$B$8 -> 0.073362363 | F6: =SUMIFS(SPU监控与预算!$G:$G,SPU监控与预算!$A:$A,$A6) -> 609510.08 | G6: =F6/规则参数!$B$9 -> 0.13547343 | H6: =SUMIFS(SPU监控与预算!$I:$I,SPU监控与预算!$A:$A,$A6) -> 258949.19 | I6: =H6/规则参数!$B$10 -> 0.053482695 | J6: =IFERROR(H6/D6,0) -> 0.10802405 | K6: =IFERROR(F6/D6,0) -> 0.25426512 | L6: =COUNTIFS(SPU监控与预算!$A:$A,$A6) -> 8 | M6: =SUMIFS(SPU监控与预算!$W:$W,SPU监控与预算!$A:$A,$A6) -> 21227.979 | N6: =SUMIFS(SPU监控与预算!$X:$X,SPU监控与预算!$A:$A,$A6) -> 22260.964
A7: 黄油枪 | B7: 维稳 | C7: 净毛利率 19.0%、广告费率 16.0%，在合理区间 | D7: =SUMIFS(SPU监控与预算!$E:$E,SPU监控与预算!$A:$A,$A7) -> 1614868.7 | E7: =D7/规则参数!$B$8 -> 0.049421559 | F7: =SUMIFS(SPU监控与预算!$G:$G,SPU监控与预算!$A:$A,$A7) -> 307537.75 | G7: =F7/规则参数!$B$9 -> 0.068355217 | H7: =SUMIFS(SPU监控与预算!$I:$I,SPU监控与预算!$A:$A,$A7) -> 258145.76 | I7: =H7/规则参数!$B$10 -> 0.053316757 | J7: =IFERROR(H7/D7,0) -> 0.15985557 | K7: =IFERROR(F7/D7,0) -> 0.19044133 | L7: =COUNTIFS(SPU监控与预算!$A:$A,$A7) -> 3 | M7: =SUMIFS(SPU监控与预算!$W:$W,SPU监控与预算!$A:$A,$A7) -> 19085.925 | N7: =SUMIFS(SPU监控与预算!$X:$X,SPU监控与预算!$A:$A,$A7) -> 19052.145
A8: 木工钉枪 | B8: 维稳 | C8: 净毛利率 11.8%、广告费率 14.8%，在合理区间 | D8: =SUMIFS(SPU监控与预算!$E:$E,SPU监控与预算!$A:$A,$A8) -> 1710642.6 | E8: =D8/规则参数!$B$8 -> 0.05235263 | F8: =SUMIFS(SPU监控与预算!$G:$G,SPU监控与预算!$A:$A,$A8) -> 201720.85 | G8: =F8/规则参数!$B$9 -> 0.044835707 | H8: =SUMIFS(SPU监控与预算!$I:$I,SPU监控与预算!$A:$A,$A8) -> 253472.5 | I8: =H8/规则参数!$B$10 -> 0.052351554 | J8: =IFERROR(H8/D8,0) -> 0.14817385 | K8: =IFERROR(F8/D8,0) -> 0.11792109 | L8: =COUNTIFS(SPU监控与预算!$A:$A,$A8) -> 14 | M8: =SUMIFS(SPU监控与预算!$W:$W,SPU监控与预算!$A:$A,$A8) -> 22900.408 | N8: =SUMIFS(SPU监控与预算!$X:$X,SPU监控与预算!$A:$A,$A8) -> 22327.654
A9: 吹叶机 | B9: 维稳 | C9: 净毛利率 13.1%、广告费率 14.1%，在合理区间 | D9: =SUMIFS(SPU监控与预算!$E:$E,SPU监控与预算!$A:$A,$A9) -> 900793.65 | E9: =D9/规则参数!$B$8 -> 0.027567954 | F9: =SUMIFS(SPU监控与预算!$G:$G,SPU监控与预算!$A:$A,$A9) -> 117557.33 | G9: =F9/规则参数!$B$9 -> 0.026129009 | H9: =SUMIFS(SPU监控与预算!$I:$I,SPU监控与预算!$A:$A,$A9) -> 126941.7 | I9: =H9/规则参数!$B$10 -> 0.02621821 | J9: =IFERROR(H9/D9,0) -> 0.14092206 | K9: =IFERROR(F9/D9,0) -> 0.13050417 | L9: =COUNTIFS(SPU监控与预算!$A:$A,$A9) -> 3 | M9: =SUMIFS(SPU监控与预算!$W:$W,SPU监控与预算!$A:$A,$A9) -> 13715.57 | N9: =SUMIFS(SPU监控与预算!$X:$X,SPU监控与预算!$A:$A,$A9) -> 12669.295
A10: 锯片机 | B10: 收缩 | C10: 净毛利率 7.6% <8% | D10: =SUMIFS(SPU监控与预算!$E:$E,SPU监控与预算!$A:$A,$A10) -> 779130.84 | E10: =D10/规则参数!$B$8 -> 0.023844576 | F10: =SUMIFS(SPU监控与预算!$G:$G,SPU监控与预算!$A:$A,$A10) -> 59132.01 | G10: =F10/规则参数!$B$9 -> 0.013143041 | H10: =SUMIFS(SPU监控与预算!$I:$I,SPU监控与预算!$A:$A,$A10) -> 123318.19 | I10: =H10/规则参数!$B$10 -> 0.02546982 | J10: =IFERROR(H10/D10,0) -> 0.15827661 | K10: =IFERROR(F10/D10,0) -> 0.075894839 | L10: =COUNTIFS(SPU监控与预算!$A:$A,$A10) -> 4 | M10: =SUMIFS(SPU监控与预算!$W:$W,SPU监控与预算!$A:$A,$A10) -> 11988.285 | N10: =SUMIFS(SPU监控与预算!$X:$X,SPU监控与预算!$A:$A,$A10) -> 9928.0908
A11: 风扇 | B11: 观察 | C11: 广告费率 17.9% ≥17%；近 30 天销售环比 -81% | D11: =SUMIFS(SPU监控与预算!$E:$E,SPU监控与预算!$A:$A,$A11) -> 684738.95 | E11: =D11/规则参数!$B$8 -> 0.0209558 | F11: =SUMIFS(SPU监控与预算!$G:$G,SPU监控与预算!$A:$A,$A11) -> 82943.24 | G11: =F11/规则参数!$B$9 -> 0.018435471 | H11: =SUMIFS(SPU监控与预算!$I:$I,SPU监控与预算!$A:$A,$A11) -> 122781.12 | I11: =H11/规则参数!$B$10 -> 0.025358895 | J11: =IFERROR(H11/D11,0) -> 0.17931085 | K11: =IFERROR(F11/D11,0) -> 0.12113118 | L11: =COUNTIFS(SPU监控与预算!$A:$A,$A11) -> 7 | M11: =SUMIFS(SPU监控与预算!$W:$W,SPU监控与预算!$A:$A,$A11) -> 1374.8444 | N11: =SUMIFS(SPU监控与预算!$X:$X,SPU监控与预算!$A:$A,$A11) -> 1178.458
A12: 热风枪 | B12: 维稳 | C12: 净毛利率 18.3%、广告费率 14.8%，在合理区间 | D12: =SUMIFS(SPU监控与预算!$E:$E,SPU监控与预算!$A:$A,$A12) -> 766016.84 | E12: =D12/规则参数!$B$8 -> 0.023443234 | F12: =SUMIFS(SPU监控与预算!$G:$G,SPU监控与预算!$A:$A,$A12) -> 140298.33 | G12: =F12/规则参数!$B$9 -> 0.031183563 | H12: =SUMIFS(SPU监控与预算!$I:$I,SPU监控与预算!$A:$A,$A12) -> 113146.81 | I12: =H12/规则参数!$B$10 -> 0.023369049 | J12: =IFERROR(H12/D12,0) -> 0.14770799 | K12: =IFERROR(F12/D12,0) -> 0.18315306 | L12: =COUNTIFS(SPU监控与预算!$A:$A,$A12) -> 6 | M12: =SUMIFS(SPU监控与预算!$W:$W,SPU监控与预算!$A:$A,$A12) -> 12152.771 | N12: =SUMIFS(SPU监控与预算!$X:$X,SPU监控与预算!$A:$A,$A12) -> 11917.108
A13: 高压清洗机 | B13: 维稳 | C13: 净毛利率 13.0%、广告费率 15.6%，在合理区间 | D13: =SUMIFS(SPU监控与预算!$E:$E,SPU监控与预算!$A:$A,$A13) -> 721986.1 | E13: =D13/规则参数!$B$8 -> 0.022095715 | F13: =SUMIFS(SPU监控与预算!$G:$G,SPU监控与预算!$A:$A,$A13) -> 93554.34 | G13: =F13/规则参数!$B$9 -> 0.020793958 | H13: =SUMIFS(SPU监控与预算!$I:$I,SPU监控与预算!$A:$A,$A13) -> 112367.96 | I13: =H13/规则参数!$B$10 -> 0.023208188 | J13: =IFERROR(H13/D13,0) -> 0.15563729 | K13: =IFERROR(F13/D13,0) -> 0.12957914 | L13: =COUNTIFS(SPU监控与预算!$A:$A,$A13) -> 4 | M13: =SUMIFS(SPU监控与预算!$W:$W,SPU监控与预算!$A:$A,$A13) -> 3181.3066 | N13: =SUMIFS(SPU监控与预算!$X:$X,SPU监控与预算!$A:$A,$A13) -> 3181.6039
... A88: 园林配件 | B88: 维稳 | C88: 广告花费 <$2,000，影响小 | D88: =SUMIFS(SPU监控与预算!$E:$E,SPU监控与预算!$A:$A,$A88) -> 2193.1 | E88: =D88/规则参数!$B$8 -> 6.711779e-05 | F88: =SUMIFS(SPU监控与预算!$G:$G,SPU监控与预算!$A:$A,$A88) -> 886.22 | G88: =F88/规则参数!$B$9 -> 0.00019697666 | H88: =SUMIFS(SPU监控与预算!$I:$I,SPU监控与预算!$A:$A,$A88) -> -0.5 | I88: =H88/规则参数!$B$10 -> -1.0326871e-07 | J88: =IFERROR(H88/D88,0) -> -0.00022798778 | K88: =IFERROR(F88/D88,0) -> 0.40409466 | L88: =COUNTIFS(SPU监控与预算!$A:$A,$A88) -> 2 | M88: =SUMIFS(SPU监控与预算!$W:$W,SPU监控与预算!$A:$A,$A88) -> -0.072436087 | N88: =SUMIFS(SPU监控与预算!$X:$X,SPU监控与预算!$A:$A,$A88) -> -0.085443
A90: 广告状态判定（按顺序）：收缩＝净毛利率<8% 或 止损/压缩/清理 SPU 占广告≥30% 或 建议预算较当前≤−20%；观察＝广告费率≥17% 或 异常 SPU 占广告≥15% 或 近30天销售环比≤−20%；加投＝净毛利率≥15%、广告费率≤13%、近30天环比>−10% 且建议预算高于当前；其余维稳；广告<$2,000 的小分类维稳。

Sheet 规则参数
A1: 参数 | B1: 值 | C1: 说明
A2: 成熟品最低净毛利率 | B2: 0.1 | C2: 建议广告费率 = 广告前毛利率 − 该值
A3: 成熟品费率上限 | B3: 0.18
A4: 新品期费率上限 | B4: 0.25 | C4: 新品期按保本投放，最长 90 天
A5: 清货品让利 | B5: 0.05 | C5: 建议费率 = 广告前毛利率 − 该值
A6: 清货品费率上限 | B6: 0.15
A7: 加投单月最大增幅 | B7: 0.3 | C7: 仅「加投」标记可上调
A8: 公司销售额（1–10/24） | B8: 32675390 | C8: 利润报表-MSKU
A9: 公司毛利额 | B9: 4499111.6
A10: 公司广告花费 | B10: 4841737.8
