Workbook

Sheet 总览
A1: 逆变器广告 9月 vs 10月 汇总（数据：领星 ASIN 表现日报 2026-09-01 ~ 2026-10-26）
A2: 金额单位：美元（领星导出已统一折算为 $）。10月仅 26 天，花费/销量的环比按“日均”比较；比率指标（ACOS 等）直接比较。
A4: 阈值（蓝字可改，SPU/ASIN 表的高亮会随之更新） | F4: 广告跑飞 ASIN 摘要
A5: ACOS 偏高 | B5: 0.5 | C5: ACOS ≥ 此值标红 | F5: 风险等级 | G5: ASIN数 | H5: 10月花费 | I5: 10月超额花费
A6: TACOS 偏高 | B6: 0.25 | C6: TACOS ≥ 此值标红 | F6: 高 | G6: =COUNTIF(广告跑飞ASIN!$A$5:$A$21,F6) -> 13 | H6: =SUMIF(广告跑飞ASIN!$A$5:$A$21,F6,广告跑飞ASIN!$F$5:$F$21) -> 10957.66 | I6: =SUMIF(广告跑飞ASIN!$A$5:$A$21,F6,广告跑飞ASIN!$Q$5:$Q$21) -> 4350.8686
A7: CPC 偏高 | B7: 1 | C7: CPC ≥ 此值标黄 | F7: 中 | G7: =COUNTIF(广告跑飞ASIN!$A$5:$A$21,F7) -> 4 | H7: =SUMIF(广告跑飞ASIN!$A$5:$A$21,F7,广告跑飞ASIN!$F$5:$F$21) -> 6013.76 | I7: =SUMIF(广告跑飞ASIN!$A$5:$A$21,F7,广告跑飞ASIN!$Q$5:$Q$21) -> 870.65844
A8: 广告CVR 偏低 | B8: 0.03 | C8: 广告CVR < 此值标黄（点击 ≥ 100 时） | F8: 低 | G8: =COUNTIF(广告跑飞ASIN!$A$5:$A$21,F8) -> 0 | H8: =SUMIF(广告跑飞ASIN!$A$5:$A$21,F8,广告跑飞ASIN!$F$5:$F$21) -> 0 | I8: =SUMIF(广告跑飞ASIN!$A$5:$A$21,F8,广告跑飞ASIN!$Q$5:$Q$21) -> 0
A9: 日均花费环比 暴涨 | B9: 0.5 | C9: 10月日均花费比9月高出此比例标红
A10: ACOS 恶化(百分点) | B10: 0.1 | C10: 10月 ACOS − 9月 ACOS ≥ 此值标红 | F10: 详见「广告跑飞ASIN」页；价格变化见「SPU价格监控」「价格变动明细」。
A11: 价格变动阈值 | B11: 0.05 | C11: SPU 周均价/挂牌价 变动 ≥ 此值标色
A13: 说明：阈值为分析假设（非业务给定），可按目标利润率调整；“品类均值”行由各 SPU 汇总求和后计算。
A15: 品类核心指标
A16: 指标 | B16: 9月 | C16: 10月 | D16: 变化
A17: 广告花费 | B17: =SPU月度汇总!C21 -> 34165.36 | C17: =SPU月度汇总!X21 -> 32021.91 | D17: =IF(N(B17)=0,"",C17/B17-1) -> -0.062737521
A18: 日均花费 | B18: =SPU月度汇总!U21 -> 1138.8453 | C18: =SPU月度汇总!AP21 -> 1231.6119 | D18: =IF(N(B18)=0,"",C18/B18-1) -> 0.081456706
A19: 广告销售额 | B19: =SPU月度汇总!D21 -> 80180.77 | C19: =SPU月度汇总!Y21 -> 83159.75 | D19: =IF(N(B19)=0,"",C19/B19-1) -> 0.037153297
A20: 销售额 | B20: =SPU月度汇总!H21 -> 213471.15 | C20: =SPU月度汇总!AC21 -> 251392.03 | D20: =IF(N(B20)=0,"",C20/B20-1) -> 0.17763937
A21: 日均销量 | B21: =SPU月度汇总!V21 -> 202.13333 | C21: =SPU月度汇总!AQ21 -> 292.11538 | D21: =IF(N(B21)=0,"",C21/B21-1) -> 0.44516186
A22: ACOS | B22: =SPU月度汇总!M21 -> 0.42610416 | C22: =SPU月度汇总!AH21 -> 0.38506501 | D22: =C22-B22 -> -0.041039154
A23: TACOS | B23: =SPU月度汇总!N21 -> 0.16004673 | C23: =SPU月度汇总!AI21 -> 0.12737838 | D23: =C23-B23 -> -0.03266835
A24: CPC | B24: =SPU月度汇总!P21 -> 0.7535867 | C24: =SPU月度汇总!AK21 -> 0.74980472 | D24: =IF(N(B24)=0,"",C24/B24-1) -> -0.0050186387
A25: CTR | B25: =SPU月度汇总!Q21 -> 0.0073967784 | C25: =SPU月度汇总!AL21 -> 0.0076380945 | D25: =C25-B25 -> 0.00024131608
A26: 广告CVR | B26: =SPU月度汇总!R21 -> 0.047488806 | C26: =SPU月度汇总!AM21 -> 0.057554968 | D26: =C26-B26 -> 0.010066162
A27: 广告单占比 | B27: =SPU月度汇总!S21 -> 0.3855659 | C27: =SPU月度汇总!AN21 -> 0.35752727 | D27: =C27-B27 -> -0.02803863
A28: 成交均价 | B28: =SPU月度汇总!T21 -> 35.203026 | C28: =SPU月度汇总!AO21 -> 33.099675 | D28: =IF(N(B28)=0,"",C28/B28-1) -> -0.059749161
A29: 结算毛利润 | B29: =SPU月度汇总!L21 -> -25524.08 | C29: =SPU月度汇总!AG21 -> 4077.36 | D29: =C29-B29 -> 29601.44
A30: 变化列：金额类为环比%，比率类为百分点差；日均花费/销量为按天数折算。

Sheet 广告跑飞ASIN
A1: 广告跑飞 ASIN 重点清单
A2: 判定规则（满足任一即入列）：①10月花费≥$100 且 ACOS≥60% 或无广告出单；②ACOS 环比恶化≥15pp；③日均花费环比≥+50% 且 ACOS 未改善且高于品类均值；④TACOS≥30%；⑤近7天(10/20–10/26)花费≥$50 且 ACOS≥80% 或零出单；⑥点击≥200 且广告CVR<2%；⑦高ACOS且当月结算亏损。等级：≥3条规则 / ACOS≥100% / 超额花费≥$500 为「高」。超额花费 = 10月花费 − 10月广告销售额 × 品类10月平均ACOS（38.5%）。
A4: 风险等级 | B4: ASIN | C4: SPU | D4: 型号 | E4: 9月花费 | F4: 10月花费 | G4: 日均花费环比 | H4: 近7天日均花费 | I4: 9月ACOS | J4: 10月ACOS | K4: 近7天ACOS | L4: 10月TACOS | M4: 9月CPC | N4: 10月CPC | O4: 10月广告CVR | P4: 10月广告订单 | Q4: 10月超额花费 | R4: 10月结算毛利润 | S4: 触发规则 | T4: 花费店铺(10月) | U4: 建议动作
A5: 高 | B5: B0CQ2JJ51T | C5: SPU07022 | D5: 米沃奇-电源逆变器-200W | E5: 2645.07 | F5: 3852.8 | G5: 0.6806884 | H5: 70.052857 | I5: 0.48262417 | J5: 0.54329908 | K5: 0.50322746 | L5: 0.27517956 | M5: 0.6824226 | N5: 0.78039295 | O5: 0.046789548 | P5: 231 | Q5: 1122.1153 | R5: -1910.08 | S5: 日均花费 +68% 且ACOS未改善；广告高花费且结算亏损 | T5: HK8-US $3057/ACOS 54%；AMZ8-CA $796/ACOS 56%；AMZ8-US $0/无出单 | U5: 花费放量但产出未跟上：回收新增预算，按 ACOS 分层调价
A6: 高 | B6: B0GXHN35JL | C6: SPU50039 | D6: 米沃奇-单包逆变器350W-修正波版-美规-红色 | E6: 1799.96 | F6: 2071.66 | G6: 0.32801669 | H6: 71.367143 | I6: 0.67312381 | J6: 0.8168652 | K6: 1.7290946 | L6: 0.40774849 | M6: 1.1553017 | N6: 1.0938015 | O6: 0.033790919 | P6: 64 | Q6: 1095.0928 | R6: -2342.14 | S6: 10月ACOS 82%；TACOS 41%；近7天ACOS 173%；广告高花费且结算亏损 | T6: AMZ5-US $2072/ACOS 82% | U6: 收紧预算，降低宽泛/自动广告竞价，否定无效词
A7: 高 | B7: B0GXJ1P8X2 | C7: SPU50039 | D7: 牧田-单包逆变器350W-修正波版-美规-蓝色 | E7: 822.37 | F7: 861.16 | G7: 0.2082714 | H7: 26.105714 | I7: 0.6183512 | J7: 0.80520622 | K7: 1.3952814 | L7: 0.4441854 | M7: 0.8348934 | N7: 0.77933032 | O7: 0.022624434 | P7: 25 | Q7: 449.33682 | R7: -602.47 | S7: 10月ACOS 81%；ACOS恶化 62%→81%；TACOS 44%；近7天ACOS 140%；广告高花费且结算亏损 | T7: AMZ5-US $861/ACOS 81% | U7: 点击转化差：检查价格/评分/Listing 与竞品差距，先降竞价再优化转化
A8: 高 | B8: B0FHPXK8SM | C8: SPU07116 | D8: 米沃奇-电源逆变器-双插脚-350W | E8: 840.11 | F8: 594.43 | G8: -0.18358219 | H8: 0 | I8: 0.56142074 | J8: 1.3466618 | L8: 1.3524219 | M8: 1.082616 | N8: 1.2131224 | O8: 0.018367347 | P8: 9 | Q8: 424.45845 | R8: -3037.01 | S8: 10月ACOS 135%；ACOS恶化 56%→135%；TACOS 135%；广告CVR 1.8% | T8: AMZ5-US $594/ACOS 135% | U8: 立即暂停/大幅降预算，排查广告组与投放词；仅保留品牌词与核心精准词
A9: 高 | B9: B0G2B7W1WS | C9: SPU07130 | D9: 牧田-电源逆变器-双插脚-550W | E9: 607.85 | F9: 504.53 | G9: -0.042280168 | H9: 17.724286 | I9: 0.55105297 | J9: 1.4808195 | L9: 0.26598728 | M9: 1.0302542 | N9: 1.0192525 | O9: 0.0060606061 | P9: 3 | Q9: 373.3345 | R9: -189.21 | S9: 10月ACOS 148%；ACOS恶化 55%→148%；近7天花$124零广告出单；广告CVR 0.6%；广告高花费且结算亏损 | T9: AMZ8-US $505/ACOS 148% | U9: 立即暂停/大幅降预算，排查广告组与投放词；仅保留品牌词与核心精准词
A10: 高 | B10: B0D4DW8QV2 | C10: SPU07022 | D10: 米沃奇-电源逆变器-200W | E10: 561.4 | F10: 536.42 | G10: 0.10250473 | H10: 22.101429 | I10: 0.67867505 | J10: 0.61500539 | K10: 0.45030125 | L10: 0.30693262 | M10: 0.64013683 | N10: 0.68420918 | O10: 0.043367347 | P10: 34 | Q10: 200.5586 | R10: -215.73 | S10: 10月ACOS 62%；TACOS 31%；广告高花费且结算亏损 | T10: AMZ15-US $342/ACOS 55%；AMZ15-CA $194/ACOS 78% | U10: 收紧预算，降低宽泛/自动广告竞价，否定无效词
A11: 高 | B11: B0FLQ5Y1XM | C11: SPU07120 | D11: 得伟-电源逆变器-双插脚-550W | E11: 420.31 | F11: 617.27 | G11: 0.69454597 | H11: 20.854286 | I11: 0.20055924 | J11: 0.51650071 | K11: 0.49262646 | L11: 0.056241128 | M11: 0.43286303 | N11: 0.59182167 | O11: 0.014381592 | P11: 15 | Q11: 157.07881 | R11: 1848.17 | S11: ACOS恶化 20%→52%；日均花费 +69% 且ACOS未改善；广告CVR 1.4% | T11: AMZ8-US $494/ACOS 57%；AMZ8-CA $124/ACOS 37% | U11: CPC 上涨推高 ACOS：下调竞价 15–25%，否定高花费零单搜索词
A12: 高 | B12: B0FM2KM4CR | C12: SPU07051 | D12: 牧田-电源逆变器200W | E12: 196.39 | F12: 424.91 | G12: 1.496465 | H12: 15.282857 | I12: 0.50644695 | J12: 0.55641254 | K12: 1.3337489 | L12: 0.72955942 | M12: 0.55011204 | N12: 0.5959467 | O12: 0.029453015 | P12: 21 | Q12: 130.85125 | R12: -288.59 | S12: 日均花费 +150% 且ACOS未改善；TACOS 73%；近7天ACOS 133%；广告高花费且结算亏损 | T12: AMZ8-US $425/ACOS 56% | U12: 点击转化差：检查价格/评分/Listing 与竞品差距，先降竞价再优化转化
A13: 高 | B13: B0F2MN7KK8 | C13: SPU07055 | D13: 得伟-双向逆变器-65W | E13: 232.37 | F13: 221.31 | G13: 0.098927109 | H13: 7.19 | I13: 0.57129862 | J13: 0.69027791 | K13: 1.0989083 | L13: 0.50861831 | M13: 0.65089636 | N13: 0.63412607 | O13: 0.037249284 | P13: 13 | Q13: 97.854307 | R13: -88.24 | S13: 10月ACOS 69%；TACOS 51%；近7天ACOS 110%；广告高花费且结算亏损 | T13: AMZ15-CA $221/ACOS 69% | U13: 收紧预算，降低宽泛/自动广告竞价，否定无效词
A14: 高 | B14: B0GXHPWWL2 | C14: SPU50039 | D14: 得伟-单包逆变器350W-修正波版-美规-黄色 | E14: 165.43 | F14: 101.49 | G14: -0.29212449 | H14: 0.0014285714 | I14: 1.0607207 | J14: 2.6429688 | L14: 0.25059878 | M14: 0.52351266 | N14: 0.48793269 | O14: 0.0048076923 | P14: 1 | Q14: 86.703504 | R14: -48.59 | S14: 10月ACOS 264%；广告CVR 0.5% | T14: HK8-US $101/ACOS 264% | U14: 立即暂停/大幅降预算，排查广告组与投放词；仅保留品牌词与核心精准词
A15: 高 | B15: B0FLQ71NRS | C15: SPU07121 | D15: 米沃奇-电源逆变器-双插脚-550W | E15: 349.65 | F15: 764.77 | G15: 1.5237435 | H15: 30.47 | I15: 0.22957525 | J15: 0.43251574 | K15: 0.66746988 | L15: 0.10020033 | M15: 0.51723373 | N15: 0.51499663 | O15: 0.012121212 | P15: 18 | Q15: 83.901899 | R15: 2187.5 | S15: ACOS恶化 23%→43%；日均花费 +152% 且ACOS未改善；广告CVR 1.2% | T15: AMZ8-US $765/ACOS 43% | U15: 点击转化差：检查价格/评分/Listing 与竞品差距，先降竞价再优化转化
A16: 高 | B16: B0GXJ4276L | C16: SPU50039 | D16: 牧田-单包逆变器350W-修正波版-美规-蓝色 | E16: 775.8 | F16: 131.68 | G16: -0.80415254 | H16: 0.0014285714 | I16: 0.70635795 | J16: 1.0180131 | L16: 0.29012713 | M16: 0.60139535 | N16: 0.42070288 | O16: 0.012779553 | P16: 4 | Q16: 81.871841 | R16: -7.23 | S16: 10月ACOS 102%；广告CVR 1.3% | T16: HK8-US $132/ACOS 102% | U16: 立即暂停/大幅降预算，排查广告组与投放词；仅保留品牌词与核心精准词
A17: 高 | B17: B0FM7FTP4N | C17: SPU07051 | D17: 牧田-电源逆变器200W-2个装 | E17: 96.79 | F17: 275.23 | G17: 2.2810526 | H17: 15.511429 | I17: 0.24022138 | J17: 0.46581254 | K17: 0.38513106 | L17: 0.38288608 | M17: 0.88798165 | N17: 1.0626641 | O17: 0.054054054 | P17: 14 | Q17: 47.710488 | R17: -214.94 | S17: ACOS恶化 24%→47%；日均花费 +228% 且ACOS未改善；TACOS 38%；广告高花费且结算亏损 | T17: AMZ15-US $275/ACOS 47% | U17: CPC 上涨推高 ACOS：下调竞价 15–25%，否定高花费零单搜索词
A18: 中 | B18: B0DQKKF484 | C18: SPU07060 | D18: 利优比-电源逆变器-200W | E18: 2474.49 | F18: 1577.74 | G18: -0.26430528 | H18: 22.68 | I18: 0.36483827 | J18: 0.49552447 | L18: 0.28006788 | M18: 0.4483584 | N18: 0.46213825 | O18: 0.023140012 | P18: 79 | Q18: 351.70071 | R18: 498.91 | S18: 近7天花$159零广告出单 | T18: AMZ5-US $1578/ACOS 50%；HK5-US $0/无出单 | U18: 点击转化差：检查价格/评分/Listing 与竞品差距，先降竞价再优化转化
A19: 中 | B19: B0CQ4PFGH5 | C19: SPU07022 | D19: 米沃奇-电源逆变器-200W | E19: 2584.13 | F19: 3709 | G19: 0.65611459 | H19: 242.01714 | I19: 0.46512293 | J19: 0.41581603 | K19: 0.43166362 | L19: 0.19943562 | M19: 1.053457 | N19: 0.6941793 | O19: 0.066067752 | P19: 353 | Q19: 274.29327 | R19: -1758.54 | S19: 广告高花费且结算亏损 | T19: HK5-US $3156/ACOS 42%；AMZ5-US $553/ACOS 37% | U19: 花费放量但产出未跟上：回收新增预算，按 ACOS 分层调价
A20: 中 | B20: B0FG2CBW2F | C20: SPU07115 | D20: 得伟-电源逆变器-双插脚-350W,得伟-电源逆变器400W-双插脚AK47,正宗AC美标110V,PD20w-美规-黄黑 | E20: 648.75 | F20: 352.41 | G20: -0.37321476 | H20: 1.2057143 | I20: 0.72844968 | J20: 0.70539843 | K20: 0.13189561 | L20: 0.20511373 | M20: 0.63853346 | N20: 0.92496063 | O20: 0.034120735 | P20: 13 | Q20: 160.03537 | R20: -224.81 | S20: 10月ACOS 71%；广告高花费且结算亏损 | T20: AMZ5-US $352/ACOS 71% | U20: 收紧预算，降低宽泛/自动广告竞价，否定无效词
A21: 中 | B21: B0DB1YHDFZ | C21: SPU07055 | D21: 得伟-双向逆变器-65W | E21: 351.93 | F21: 374.61 | G21: 0.22820535 | H21: 8.2285714 | I21: 0.44897048 | J21: 0.4974438 | K21: 0.28849043 | L21: 0.72292016 | M21: 0.59347386 | N21: 0.61919008 | O21: 0.039669421 | P21: 24 | Q21: 84.629093 | R21: -226.13 | S21: TACOS 72%；广告高花费且结算亏损 | T21: AMZ5-US $375/ACOS 50% | U21: 收紧预算，降低宽泛/自动广告竞价，否定无效词
F22: =SUM(F5:F21) -> 16971.42 | P22: 合计 | Q22: =SUM(Q5:Q21) -> 5221.527

Sheet SPU月度汇总
A1: SPU 维度 · 9月 vs 10月 广告与销售汇总
A3: SPU | B3: 款名（品牌） | C3: 2026年9月（30天） | X3: 2026年10月（26天） | AS3: 10月 vs 9月
C4: 广告花费 | D4: 广告销售额 | E4: 广告订单量 | F4: 点击 | G4: 展示 | H4: 销售额 | I4: 销量 | J4: 订单量 | K4: Sessions-Total | L4: 结算毛利润 | M4: ACOS | N4: TACOS | O4: ROAS | P4: CPC | Q4: CTR | R4: 广告CVR | S4: 广告单占比 | T4: 成交均价 | U4: 日均花费 | V4: 日均销量 | W4: 毛利率 | X4: 广告花费 | Y4: 广告销售额 | Z4: 广告订单量 | AA4: 点击 | AB4: 展示 | AC4: 销售额 | AD4: 销量 | AE4: 订单量 | AF4: Sessions-Total | AG4: 结算毛利润 | AH4: ACOS | AI4: TACOS | AJ4: ROAS | AK4: CPC | AL4: CTR | AM4: 广告CVR | AN4: 广告单占比 | AO4: 成交均价 | AP4: 日均花费 | AQ4: 日均销量 | AR4: 毛利率 | AS4: 日均花费环比 | AT4: 广告销售额日均环比 | AU4: 日均销量环比 | AV4: ACOS变化(pp) | AW4: TACOS变化(pp) | AX4: CPC环比 | AY4: 广告CVR变化(pp) | AZ4: 成交均价环比
A5: SPU07021 | B5: 逆变器-200W（得伟） | C5: 6278.14 | D5: 13794.77 | E5: 456 | F5: 5664 | G5: 1017432 | H5: 48596.36 | I5: 1820 | J5: 1622 | K5: 57828 | L5: -1543.86 | M5: =IF(N(D5)=0,"",C5/D5) -> 0.45511016 | N5: =IF(N(H5)=0,"",C5/H5) -> 0.12918951 | O5: =IF(N(C5)=0,"",D5/C5) -> 2.1972702 | P5: =IF(N(F5)=0,"",C5/F5) -> 1.1084287 | Q5: =IF(N(G5)=0,"",F5/G5) -> 0.0055669568 | R5: =IF(N(F5)=0,"",E5/F5) -> 0.080508475 | S5: =IF(N(J5)=0,"",E5/J5) -> 0.2811344 | T5: =IF(N(I5)=0,"",H5/I5) -> 26.701297 | U5: =IF(N(30)=0,"",C5/30) -> 209.27133 | V5: =IF(N(30)=0,"",I5/30) -> 60.666667 | W5: =IF(N(H5)=0,"",L5/H5) -> -0.031769046 | X5: 9619.07 | Y5: 33108.67 | Z5: 1064 | AA5: 11315 | AB5: 1410010 | AC5: 92025.43 | AD5: 3320 | AE5: 2890 | AF5: 79851 | AG5: -816.98 | AH5: =IF(N(Y5)=0,"",X5/Y5) -> 0.29053024 | AI5: =IF(N(AC5)=0,"",X5/AC5) -> 0.10452622 | AJ5: =IF(N(X5)=0,"",Y5/X5) -> 3.4419824 | AK5: =IF(N(AA5)=0,"",X5/AA5) -> 0.85011666 | AL5: =IF(N(AB5)=0,"",AA5/AB5) -> 0.0080247658 | AM5: =IF(N(AA5)=0,"",Z5/AA5) -> 0.094034468 | AN5: =IF(N(AE5)=0,"",Z5/AE5) -> 0.36816609 | AO5: =IF(N(AD5)=0,"",AC5/AD5) -> 27.718503 | AP5: =IF(N(26)=0,"",X5/26) -> 369.96423 | AQ5: =IF(N(26)=0,"",AD5/26) -> 127.69231 | AR5: =IF(N(AC5)=0,"",AG5/AC5) -> -0.0088777635 | AS5: =IF(OR(U5="",AP5=""),"",IF(N(U5)=0,"",AP5/U5-1)) -> 0.76786866 | AT5: =IF(N(D5)=0,"",(Y5/26)/(D5/30)-1) -> 1.769333 | AU5: =IF(OR(V5="",AQ5=""),"",IF(N(V5)=0,"",AQ5/V5-1)) -> 1.1048183 | AV5: =IF(OR(M5="",AH5=""),"",AH5-M5) -> -0.16457992 | AW5: =IF(OR(N5="",AI5=""),"",AI5-N5) -> -0.024663295 | AX5: =IF(OR(P5="",AK5=""),"",IF(N(P5)=0,"",AK5/P5-1)) -> -0.23304342 | AY5: =IF(OR(R5="",AM5=""),"",AM5-R5) -> 0.013525993 | AZ5: =IF(OR(T5="",AO5=""),"",IF(N(T5)=0,"",AO5/T5-1)) -> 0.038095764
A6: SPU07022 | B6: 逆变器-200W（米沃奇） | C6: 6127.31 | D6: 14149.59 | E6: 486 | F6: 7661 | G6: 1418377 | H6: 35692.21 | I6: 1281 | J6: 1165 | K6: 34400 | L6: -1523.49 | M6: =IF(N(D6)=0,"",C6/D6) -> 0.43303799 | N6: =IF(N(H6)=0,"",C6/H6) -> 0.17167079 | O6: =IF(N(C6)=0,"",D6/C6) -> 2.3092662 | P6: =IF(N(F6)=0,"",C6/F6) -> 0.79980551 | Q6: =IF(N(G6)=0,"",F6/G6) -> 0.0054012438 | R6: =IF(N(F6)=0,"",E6/F6) -> 0.063438193 | S6: =IF(N(J6)=0,"",E6/J6) -> 0.41716738 | T6: =IF(N(I6)=0,"",H6/I6) -> 27.862771 | U6: =IF(N(30)=0,"",C6/30) -> 204.24367 | V6: =IF(N(30)=0,"",I6/30) -> 42.7 | W6: =IF(N(H6)=0,"",L6/H6) -> -0.042684104 | X6: 8643.51 | Y6: 21270.14 | Z6: 710 | AA6: 11822 | AB6: 2052166 | AC6: 46126.14 | AD6: 1718 | AE6: 1556 | AF6: 45311 | AG6: -3526.95 | AH6: =IF(N(Y6)=0,"",X6/Y6) -> 0.40636827 | AI6: =IF(N(AC6)=0,"",X6/AC6) -> 0.18738854 | AJ6: =IF(N(X6)=0,"",Y6/X6) -> 2.4608221 | AK6: =IF(N(AA6)=0,"",X6/AA6) -> 0.73113771 | AL6: =IF(N(AB6)=0,"",AA6/AB6) -> 0.0057607426 | AM6: =IF(N(AA6)=0,"",Z6/AA6) -> 0.06005752 | AN6: =IF(N(AE6)=0,"",Z6/AE6) -> 0.4562982 | AO6: =IF(N(AD6)=0,"",AC6/AD6) -> 26.848743 | AP6: =IF(N(26)=0,"",X6/26) -> 332.44269 | AQ6: =IF(N(26)=0,"",AD6/26) -> 66.076923 | AR6: =IF(N(AC6)=0,"",AG6/AC6) -> -0.076463151 | AS6: =IF(OR(U6="",AP6=""),"",IF(N(U6)=0,"",AP6/U6-1)) -> 0.62767687 | AT6: =IF(N(D6)=0,"",(Y6/26)/(D6/30)-1) -> 0.73450038 | AU6: =IF(OR(V6="",AQ6=""),"",IF(N(V6)=0,"",AQ6/V6-1)) -> 0.54746892 | AV6: =IF(OR(M6="",AH6=""),"",AH6-M6) -> -0.026669719 | AW6: =IF(OR(N6="",AI6=""),"",AI6-N6) -> 0.015717746 | AX6: =IF(OR(P6="",AK6=""),"",IF(N(P6)=0,"",AK6/P6-1)) -> -0.085855622 | AY6: =IF(OR(R6="",AM6=""),"",AM6-R6) -> -0.0033806736 | AZ6: =IF(OR(T6="",AO6=""),"",IF(N(T6)=0,"",AO6/T6-1)) -> -0.036393672
A7: SPU50039 | B7: 单包逆变器（得伟/米沃奇/牧田） | C7: 6794.83 | D7: 12233.82 | E7: 286 | F7: 7376 | G7: 762158 | H7: 24210.94 | I7: 584 | J7: 554 | K7: 19274 | L7: -3088.64 | M7: =IF(N(D7)=0,"",C7/D7) -> 0.5554136 | N7: =IF(N(H7)=0,"",C7/H7) -> 0.28065123 | O7: =IF(N(C7)=0,"",D7/C7) -> 1.8004601 | P7: =IF(N(F7)=0,"",C7/F7) -> 0.92120797 | Q7: =IF(N(G7)=0,"",F7/G7) -> 0.0096777833 | R7: =IF(N(F7)=0,"",E7/F7) -> 0.038774403 | S7: =IF(N(J7)=0,"",E7/J7) -> 0.51624549 | T7: =IF(N(I7)=0,"",H7/I7) -> 41.457089 | U7: =IF(N(30)=0,"",C7/30) -> 226.49433 | V7: =IF(N(30)=0,"",I7/30) -> 19.466667 | W7: =IF(N(H7)=0,"",L7/H7) -> -0.12757208 | X7: 4577.37 | Y7: 7518.68 | Z7: 183 | AA7: 5038 | AB7: 498105 | AC7: 15346.59 | AD7: 367 | AE7: 350 | AF7: 13394 | AG7: -3097.11 | AH7: =IF(N(Y7)=0,"",X7/Y7) -> 0.60879968 | AI7: =IF(N(AC7)=0,"",X7/AC7) -> 0.29826626 | AJ7: =IF(N(X7)=0,"",Y7/X7) -> 1.6425764 | AK7: =IF(N(AA7)=0,"",X7/AA7) -> 0.90856888 | AL7: =IF(N(AB7)=0,"",AA7/AB7) -> 0.010114333 | AM7: =IF(N(AA7)=0,"",Z7/AA7) -> 0.036323938 | AN7: =IF(N(AE7)=0,"",Z7/AE7) -> 0.52285714 | AO7: =IF(N(AD7)=0,"",AC7/AD7) -> 41.816322 | AP7: =IF(N(26)=0,"",X7/26) -> 176.05269 | AQ7: =IF(N(26)=0,"",AD7/26) -> 14.115385 | AR7: =IF(N(AC7)=0,"",AG7/AC7) -> -0.20181096 | AS7: =IF(OR(U7="",AP7=""),"",IF(N(U7)=0,"",AP7/U7-1)) -> -0.22270597 | AT7: =IF(N(D7)=0,"",(Y7/26)/(D7/30)-1) -> -0.29086745 | AU7: =IF(OR(V7="",AQ7=""),"",IF(N(V7)=0,"",AQ7/V7-1)) -> -0.27489463 | AV7: =IF(OR(M7="",AH7=""),"",AH7-M7) -> 0.053386084 | AW7: =IF(OR(N7="",AI7=""),"",AI7-N7) -> 0.017615034 | AX7: =IF(OR(P7="",AK7=""),"",IF(N(P7)=0,"",AK7/P7-1)) -> -0.013720132 | AY7: =IF(OR(R7="",AM7=""),"",AM7-R7) -> -0.0024504654 | AZ7: =IF(OR(T7="",AO7=""),"",IF(N(T7)=0,"",AO7/T7-1)) -> 0.0086651642
A8: SPU07060 | B8: 逆变器-200W（利优比） | C8: 6271.94 | D8: 19415.76 | E8: 495 | F8: 11899 | G8: 1390844 | H8: 47276.01 | I8: 1203 | J8: 1159 | K8: 38122 | L8: 4486.43 | M8: =IF(N(D8)=0,"",C8/D8) -> 0.32303345 | N8: =IF(N(H8)=0,"",C8/H8) -> 0.13266644 | O8: =IF(N(C8)=0,"",D8/C8) -> 3.0956546 | P8: =IF(N(F8)=0,"",C8/F8) -> 0.52709808 | Q8: =IF(N(G8)=0,"",F8/G8) -> 0.008555237 | R8: =IF(N(F8)=0,"",E8/F8) -> 0.041600134 | S8: =IF(N(J8)=0,"",E8/J8) -> 0.42709232 | T8: =IF(N(I8)=0,"",H8/I8) -> 39.298429 | U8: =IF(N(30)=0,"",C8/30) -> 209.06467 | V8: =IF(N(30)=0,"",I8/30) -> 40.1 | W8: =IF(N(H8)=0,"",L8/H8) -> 0.09489866 | X8: 2346.6 | Y8: 6844.74 | Z8: 172 | AA8: 4420 | AB8: 418774 | AC8: 49465.86 | AD8: 1217 | AE8: 1166 | AF8: 36883 | AG8: 11479.28 | AH8: =IF(N(Y8)=0,"",X8/Y8) -> 0.3428326 | AI8: =IF(N(AC8)=0,"",X8/AC8) -> 0.047438779 | AJ8: =IF(N(X8)=0,"",Y8/X8) -> 2.9168755 | AK8: =IF(N(AA8)=0,"",X8/AA8) -> 0.53090498 | AL8: =IF(N(AB8)=0,"",AA8/AB8) -> 0.010554619 | AM8: =IF(N(AA8)=0,"",Z8/AA8) -> 0.038914027 | AN8: =IF(N(AE8)=0,"",Z8/AE8) -> 0.14751286 | AO8: =IF(N(AD8)=0,"",AC8/AD8) -> 40.645735 | AP8: =IF(N(26)=0,"",X8/26) -> 90.253846 | AQ8: =IF(N(26)=0,"",AD8/26) -> 46.807692 | AR8: =IF(N(AC8)=0,"",AG8/AC8) -> 0.2320647 | AS8: =IF(OR(U8="",AP8=""),"",IF(N(U8)=0,"",AP8/U8-1)) -> -0.56829699 | AT8: =IF(N(D8)=0,"",(Y8/26)/(D8/30)-1) -> -0.59322855 | AU8: =IF(OR(V8="",AQ8=""),"",IF(N(V8)=0,"",AQ8/V8-1)) -> 0.16727412 | AV8: =IF(OR(M8="",AH8=""),"",AH8-M8) -> 0.019799145 | AW8: =IF(OR(N8="",AI8=""),"",AI8-N8) -> -0.085227662 | AX8: =IF(OR(P8="",AK8=""),"",IF(N(P8)=0,"",AK8/P8-1)) -> 0.0072223787 | AY8: =IF(OR(R8="",AM8=""),"",AM8-R8) -> -0.0026861073 | AZ8: =IF(OR(T8="",AO8=""),"",IF(N(T8)=0,"",AO8/T8-1)) -> 0.034283978
A9: SPU07051 | B9: 逆变器-200W（牧田款）（牧田/工匠） | C9: 3088.11 | D9: 7084.84 | E9: 192 | F9: 4198 | G9: 687156 | H9: 16435.4 | I9: 477 | J9: 421 | K9: 15853 | L9: 1354.99 | M9: =IF(N(D9)=0,"",C9/D9) -> 0.43587576 | N9: =IF(N(H9)=0,"",C9/H9) -> 0.18789381 | O9: =IF(N(C9)=0,"",D9/C9) -> 2.2942317 | P9: =IF(N(F9)=0,"",C9/F9) -> 0.73561458 | Q9: =IF(N(G9)=0,"",F9/G9) -> 0.0061092387 | R9: =IF(N(F9)=0,"",E9/F9) -> 0.045736065 | S9: =IF(N(J9)=0,"",E9/J9) -> 0.45605701 | T9: =IF(N(I9)=0,"",H9/I9) -> 34.455765 | U9: =IF(N(30)=0,"",C9/30) -> 102.937 | V9: =IF(N(30)=0,"",I9/30) -> 15.9 | W9: =IF(N(H9)=0,"",L9/H9) -> 0.082443384 | X9: 2360.78 | Y9: 5842.8 | Z9: 164 | AA9: 3580 | AB9: 563106 | AC9: 12961.03 | AD9: 384 | AE9: 357 | AF9: 13129 | AG9: 498.68 | AH9: =IF(N(Y9)=0,"",X9/Y9) -> 0.40404943 | AI9: =IF(N(AC9)=0,"",X9/AC9) -> 0.18214447 | AJ9: =IF(N(X9)=0,"",Y9/X9) -> 2.4749447 | AK9: =IF(N(AA9)=0,"",X9/AA9) -> 0.65943575 | AL9: =IF(N(AB9)=0,"",AA9/AB9) -> 0.0063575952 | AM9: =IF(N(AA9)=0,"",Z9/AA9) -> 0.045810056 | AN9: =IF(N(AE9)=0,"",Z9/AE9) -> 0.45938375 | AO9: =IF(N(AD9)=0,"",AC9/AD9) -> 33.752682 | AP9: =IF(N(26)=0,"",X9/26) -> 90.799231 | AQ9: =IF(N(26)=0,"",AD9/26) -> 14.769231 | AR9: =IF(N(AC9)=0,"",AG9/AC9) -> 0.038475337 | AS9: =IF(OR(U9="",AP9=""),"",IF(N(U9)=0,"",AP9/U9-1)) -> -0.11791454 | AT9: =IF(N(D9)=0,"",(Y9/26)/(D9/30)-1) -> -0.048434078 | AU9: =IF(OR(V9="",AQ9=""),"",IF(N(V9)=0,"",AQ9/V9-1)) -> -0.071117562 | AV9: =IF(OR(M9="",AH9=""),"",AH9-M9) -> -0.031826329 | AW9: =IF(OR(N9="",AI9=""),"",AI9-N9) -> -0.0057493399 | AX9: =IF(OR(P9="",AK9=""),"",IF(N(P9)=0,"",AK9/P9-1)) -> -0.10355807 | AY9: =IF(OR(R9="",AM9=""),"",AM9-R9) -> 7.3991073e-05 | AZ9: =IF(OR(T9="",AO9=""),"",IF(N(T9)=0,"",AO9/T9-1)) -> -0.020405378
A10: SPU07120 | B10: 逆变器-550W（得伟） | C10: 940.9 | D10: 3326.48 | E10: 43 | F10: 1426 | G10: 114221 | H10: 11977.08 | I10: 127 | J10: 124 | K10: 5956 | L10: -10430.65 | M10: =IF(N(D10)=0,"",C10/D10) -> 0.28285154 | N10: =IF(N(H10)=0,"",C10/H10) -> 0.07855838 | O10: =IF(N(C10)=0,"",D10/C10) -> 3.5354235 | P10: =IF(N(F10)=0,"",C10/F10) -> 0.65981767 | Q10: =IF(N(G10)=0,"",F10/G10) -> 0.012484569 | R10: =IF(N(F10)=0,"",E10/F10) -> 0.030154278 | S10: =IF(N(J10)=0,"",E10/J10) -> 0.34677419 | T10: =IF(N(I10)=0,"",H10/I10) -> 94.307717 | U10: =IF(N(30)=0,"",C10/30) -> 31.363333 | V10: =IF(N(30)=0,"",I10/30) -> 4.2333333 | W10: =IF(N(H10)=0,"",L10/H10) -> -0.87088422 | X10: 780.95 | Y10: 1528.41 | Z10: 26 | AA10: 1177 | AB10: 82939 | AC10: 11536.37 | AD10: 114 | AE10: 106 | AF10: 5211 | AG10: 2153.1 | AH10: =IF(N(Y10)=0,"",X10/Y10) -> 0.51095583 | AI10: =IF(N(AC10)=0,"",X10/AC10) -> 0.067694604 | AJ10: =IF(N(X10)=0,"",Y10/X10) -> 1.9571163 | AK10: =IF(N(AA10)=0,"",X10/AA10) -> 0.66350892 | AL10: =IF(N(AB10)=0,"",AA10/AB10) -> 0.014191153 | AM10: =IF(N(AA10)=0,"",Z10/AA10) -> 0.022090059 | AN10: =IF(N(AE10)=0,"",Z10/AE10) -> 0.24528302 | AO10: =IF(N(AD10)=0,"",AC10/AD10) -> 101.19623 | AP10: =IF(N(26)=0,"",X10/26) -> 30.036538 | AQ10: =IF(N(26)=0,"",AD10/26) -> 4.3846154 | AR10: =IF(N(AC10)=0,"",AG10/AC10) -> 0.18663583 | AS10: =IF(OR(U10="",AP10=""),"",IF(N(U10)=0,"",AP10/U10-1)) -> -0.042304013 | AT10: =IF(N(D10)=0,"",(Y10/26)/(D10/30)-1) -> -0.469845 | AU10: =IF(OR(V10="",AQ10=""),"",IF(N(V10)=0,"",AQ10/V10-1)) -> 0.035735918 | AV10: =IF(OR(M10="",AH10=""),"",AH10-M10) -> 0.22810429 | AW10: =IF(OR(N10="",AI10=""),"",AI10-N10) -> -0.010863776 | AX10: =IF(OR(P10="",AK10=""),"",IF(N(P10)=0,"",AK10/P10-1)) -> 0.0055943472 | AY10: =IF(OR(R10="",AM10=""),"",AM10-R10) -> -0.0080642182 | AZ10: =IF(OR(T10="",AO10=""),"",IF(N(T10)=0,"",AO10/T10-1)) -> 0.073042926
A11: SPU07121 | B11: 逆变器-550W（米沃奇） | C11: 647.67 | D11: 2431.26 | E11: 28 | F11: 947 | G11: 84718 | H11: 11943.21 | I11: 126 | J11: 120 | K11: 3577 | L11: -1756.35 | M11: =IF(N(D11)=0,"",C11/D11) -> 0.26639273 | N11: =IF(N(H11)=0,"",C11/H11) -> 0.054229139 | O11: =IF(N(C11)=0,"",D11/C11) -> 3.7538561 | P11: =IF(N(F11)=0,"",C11/F11) -> 0.68391763 | Q11: =IF(N(G11)=0,"",F11/G11) -> 0.011178262 | R11: =IF(N(F11)=0,"",E11/F11) -> 0.029567054 | S11: =IF(N(J11)=0,"",E11/J11) -> 0.23333333 | T11: =IF(N(I11)=0,"",H11/I11) -> 94.787381 | U11: =IF(N(30)=0,"",C11/30) -> 21.589 | V11: =IF(N(30)=0,"",I11/30) -> 4.2 | W11: =IF(N(H11)=0,"",L11/H11) -> -0.14705845 | X11: 1027.4 | Y11: 2387.99 | Z11: 26 | AA11: 1690 | AB11: 156231 | AC11: 10303.59 | AD11: 106 | AE11: 104 | AF11: 4300 | AG11: 2550.54 | AH11: =IF(N(Y11)=0,"",X11/Y11) -> 0.43023631 | AI11: =IF(N(AC11)=0,"",X11/AC11) -> 0.099712819 | AJ11: =IF(N(X11)=0,"",Y11/X11) -> 2.3243041 | AK11: =IF(N(AA11)=0,"",X11/AA11) -> 0.60792899 | AL11: =IF(N(AB11)=0,"",AA11/AB11) -> 0.010817315 | AM11: =IF(N(AA11)=0,"",Z11/AA11) -> 0.015384615 | AN11: =IF(N(AE11)=0,"",Z11/AE11) -> 0.25 | AO11: =IF(N(AD11)=0,"",AC11/AD11) -> 97.203679 | AP11: =IF(N(26)=0,"",X11/26) -> 39.515385 | AQ11: =IF(N(26)=0,"",AD11/26) -> 4.0769231 | AR11: =IF(N(AC11)=0,"",AG11/AC11) -> 0.24753896 | AS11: =IF(OR(U11="",AP11=""),"",IF(N(U11)=0,"",AP11/U11-1)) -> 0.83034808 | AT11: =IF(N(D11)=0,"",(Y11/26)/(D11/30)-1) -> 0.13331074 | AU11: =IF(OR(V11="",AQ11=""),"",IF(N(V11)=0,"",AQ11/V11-1)) -> -0.029304029 | AV11: =IF(OR(M11="",AH11=""),"",AH11-M11) -> 0.16384357 | AW11: =IF(OR(N11="",AI11=""),"",AI11-N11) -> 0.045483679 | AX11: =IF(OR(P11="",AK11=""),"",IF(N(P11)=0,"",AK11/P11-1)) -> -0.11110788 | AY11: =IF(OR(R11="",AM11=""),"",AM11-R11) -> -0.014182438 | AZ11: =IF(OR(T11="",AO11=""),"",IF(N(T11)=0,"",AO11/T11-1)) -> 0.025491772
A12: SPU07116 | B12: 电源逆变器350W-AC美标110V PD20W（米沃奇） | C12: 884.89 | D12: 1604.97 | E12: 25 | F12: 1005 | G12: 93601 | H12: 1431.16 | I12: 28 | J12: 27 | K12: 1945 | L12: -2584.79 | M12: =IF(N(D12)=0,"",C12/D12) -> 0.55134364 | N12: =IF(N(H12)=0,"",C12/H12) -> 0.61830264 | O12: =IF(N(C12)=0,"",D12/C12) -> 1.8137509 | P12: =IF(N(F12)=0,"",C12/F12) -> 0.88048756 | Q12: =IF(N(G12)=0,"",F12/G12) -> 0.010737065 | R12: =IF(N(F12)=0,"",E12/F12) -> 0.024875622 | S12: =IF(N(J12)=0,"",E12/J12) -> 0.92592593 | T12: =IF(N(I12)=0,"",H12/I12) -> 51.112857 | U12: =IF(N(30)=0,"",C12/30) -> 29.496333 | V12: =IF(N(30)=0,"",I12/30) -> 0.93333333 | W12: =IF(N(H12)=0,"",L12/H12) -> -1.8060804 | X12: 634.88 | Y12: 538.59 | Z12: 11 | AA12: 689 | AB12: 69389 | AC12: 705.89 | AD12: 13 | AE12: 12 | AF12: 1380 | AG12: -4480.38 | AH12: =IF(N(Y12)=0,"",X12/Y12) -> 1.1787816 | AI12: =IF(N(AC12)=0,"",X12/AC12) -> 0.89940359 | AJ12: =IF(N(X12)=0,"",Y12/X12) -> 0.84833354 | AK12: =IF(N(AA12)=0,"",X12/AA12) -> 0.92145138 | AL12: =IF(N(AB12)=0,"",AA12/AB12) -> 0.0099295277 | AM12: =IF(N(AA12)=0,"",Z12/AA12) -> 0.015965167 | AN12: =IF(N(AE12)=0,"",Z12/AE12) -> 0.91666667 | AO12: =IF(N(AD12)=0,"",AC12/AD12) -> 54.299231 | AP12: =IF(N(26)=0,"",X12/26) -> 24.418462 | AQ12: =IF(N(26)=0,"",AD12/26) -> 0.5 | AR12: =IF(N(AC12)=0,"",AG12/AC12) -> -6.3471362 | AS12: =IF(OR(U12="",AP12=""),"",IF(N(U12)=0,"",AP12/U12-1)) -> -0.17215264 | AT12: =IF(N(D12)=0,"",(Y12/26)/(D12/30)-1) -> -0.6127965 | AU12: =IF(OR(V12="",AQ12=""),"",IF(N(V12)=0,"",AQ12/V12-1)) -> -0.46428571 | AV12: =IF(OR(M12="",AH12=""),"",AH12-M12) -> 0.62743799 | AW12: =IF(OR(N12="",AI12=""),"",AI12-N12) -> 0.28110095 | AX12: =IF(OR(P12="",AK12=""),"",IF(N(P12)=0,"",AK12/P12-1)) -> 0.046524015 | AY12: =IF(OR(R12="",AM12=""),"",AM12-R12) -> -0.008910455 | AZ12: =IF(OR(T12="",AO12=""),"",IF(N(T12)=0,"",AO12/T12-1)) -> 0.062339963
A13: SPU07130 | B13: 电源逆变器-550W（牧田） | C13: 754.08 | D13: 1338.04 | E13: 16 | F13: 788 | G13: 67418 | H13: 4919.69 | I13: 51 | J13: 47 | K13: 2087 | L13: 564.85 | M13: =IF(N(D13)=0,"",C13/D13) -> 0.5635706 | N13: =IF(N(H13)=0,"",C13/H13) -> 0.15327795 | O13: =IF(N(C13)=0,"",D13/C13) -> 1.7744006 | P13: =IF(N(F13)=0,"",C13/F13) -> 0.95695431 | Q13: =IF(N(G13)=0,"",F13/G13) -> 0.011688273 | R13: =IF(N(F13)=0,"",E13/F13) -> 0.020304569 | S13: =IF(N(J13)=0,"",E13/J13) -> 0.34042553 | T13: =IF(N(I13)=0,"",H13/I13) -> 96.46451 | U13: =IF(N(30)=0,"",C13/30) -> 25.136 | V13: =IF(N(30)=0,"",I13/30) -> 1.7 | W13: =IF(N(H13)=0,"",L13/H13) -> 0.11481414 | X13: 543.62 | Y13: 387.7 | Z13: 4 | AA13: 540 | AB13: 43689 | AC13: 3150.09 | AD13: 31 | AE13: 31 | AF13: 1606 | AG13: -13.02 | AH13: =IF(N(Y13)=0,"",X13/Y13) -> 1.4021666 | AI13: =IF(N(AC13)=0,"",X13/AC13) -> 0.17257285 | AJ13: =IF(N(X13)=0,"",Y13/X13) -> 0.713182 | AK13: =IF(N(AA13)=0,"",X13/AA13) -> 1.0067037 | AL13: =IF(N(AB13)=0,"",AA13/AB13) -> 0.012360091 | AM13: =IF(N(AA13)=0,"",Z13/AA13) -> 0.0074074074 | AN13: =IF(N(AE13)=0,"",Z13/AE13) -> 0.12903226 | AO13: =IF(N(AD13)=0,"",AC13/AD13) -> 101.61581 | AP13: =IF(N(26)=0,"",X13/26) -> 20.908462 | AQ13: =IF(N(26)=0,"",AD13/26) -> 1.1923077 | AR13: =IF(N(AC13)=0,"",AG13/AC13) -> -0.0041332152 | AS13: =IF(OR(U13="",AP13=""),"",IF(N(U13)=0,"",AP13/U13-1)) -> -0.1681866 | AT13: =IF(N(D13)=0,"",(Y13/26)/(D13/30)-1) -> -0.66567057 | AU13: =IF(OR(V13="",AQ13=""),"",IF(N(V13)=0,"",AQ13/V13-1)) -> -0.29864253 | AV13: =IF(OR(M13="",AH13=""),"",AH13-M13) -> 0.83859603 | AW13: =IF(OR(N13="",AI13=""),"",AI13-N13) -> 0.019294897 | AX13: =IF(OR(P13="",AK13=""),"",IF(N(P13)=0,"",AK13/P13-1)) -> 0.051987214 | AY13: =IF(OR(R13="",AM13=""),"",AM13-R13) -> -0.012897161 | AZ13: =IF(OR(T13="",AO13=""),"",IF(N(T13)=0,"",AO13/T13-1)) -> 0.053400952
A14: SPU07055 | B14: 逆变器-双向65W（得伟） | C14: 641.88 | D14: 1218.98 | E14: 42 | F14: 1115 | G14: 166518 | H14: 1471.75 | I14: 61 | J14: 58 | K14: 2087 | L14: -348.81 | M14: =IF(N(D14)=0,"",C14/D14) -> 0.5265714 | N14: =IF(N(H14)=0,"",C14/H14) -> 0.43613385 | O14: =IF(N(C14)=0,"",D14/C14) -> 1.8990777 | P14: =IF(N(F14)=0,"",C14/F14) -> 0.57567713 | Q14: =IF(N(G14)=0,"",F14/G14) -> 0.0066959728 | R14: =IF(N(F14)=0,"",E14/F14) -> 0.037668161 | S14: =IF(N(J14)=0,"",E14/J14) -> 0.72413793 | T14: =IF(N(I14)=0,"",H14/I14) -> 24.127049 | U14: =IF(N(30)=0,"",C14/30) -> 21.396 | V14: =IF(N(30)=0,"",I14/30) -> 2.0333333 | W14: =IF(N(H14)=0,"",L14/H14) -> -0.23700357 | X14: 595.97 | Y14: 1073.72 | Z14: 37 | AA14: 954 | AB14: 119856 | AC14: 1316.56 | AD14: 58 | AE14: 53 | AF14: 1642 | AG14: -305.44 | AH14: =IF(N(Y14)=0,"",X14/Y14) -> 0.5550516 | AI14: =IF(N(AC14)=0,"",X14/AC14) -> 0.45267212 | AJ14: =IF(N(X14)=0,"",Y14/X14) -> 1.8016343 | AK14: =IF(N(AA14)=0,"",X14/AA14) -> 0.6247065 | AL14: =IF(N(AB14)=0,"",AA14/AB14) -> 0.0079595515 | AM14: =IF(N(AA14)=0,"",Z14/AA14) -> 0.038784067 | AN14: =IF(N(AE14)=0,"",Z14/AE14) -> 0.69811321 | AO14: =IF(N(AD14)=0,"",AC14/AD14) -> 22.69931 | AP14: =IF(N(26)=0,"",X14/26) -> 22.921923 | AQ14: =IF(N(26)=0,"",AD14/26) -> 2.2307692 | AR14: =IF(N(AC14)=0,"",AG14/AC14) -> -0.23199854 | AS14: =IF(OR(U14="",AP14=""),"",IF(N(U14)=0,"",AP14/U14-1)) -> 0.071318147 | AT14: =IF(N(D14)=0,"",(Y14/26)/(D14/30)-1) -> 0.016347842 | AU14: =IF(OR(V14="",AQ14=""),"",IF(N(V14)=0,"",AQ14/V14-1)) -> 0.097099622 | AV14: =IF(OR(M14="",AH14=""),"",AH14-M14) -> 0.028480201 | AW14: =IF(OR(N14="",AI14=""),"",AI14-N14) -> 0.016538261 | AX14: =IF(OR(P14="",AK14=""),"",IF(N(P14)=0,"",AK14/P14-1)) -> 0.085168172 | AY14: =IF(OR(R14="",AM14=""),"",AM14-R14) -> 0.0011159057 | AZ14: =IF(OR(T14="",AO14=""),"",IF(N(T14)=0,"",AO14/T14-1)) -> -0.059175858
A15: SPU07115 | B15: 电源逆变器350W-AC美标110V PD20W（得伟） | C15: 769.84 | D15: 1455.43 | E15: 24 | F15: 1591 | G15: 97977 | H15: 2056.15 | I15: 40 | J15: 40 | K15: 3348 | L15: -2463.18 | M15: =IF(N(D15)=0,"",C15/D15) -> 0.52894334 | N15: =IF(N(H15)=0,"",C15/H15) -> 0.37440848 | O15: =IF(N(C15)=0,"",D15/C15) -> 1.8905617 | P15: =IF(N(F15)=0,"",C15/F15) -> 0.48387178 | Q15: =IF(N(G15)=0,"",F15/G15) -> 0.016238505 | R15: =IF(N(F15)=0,"",E15/F15) -> 0.015084852 | S15: =IF(N(J15)=0,"",E15/J15) -> 0.6 | T15: =IF(N(I15)=0,"",H15/I15) -> 51.40375 | U15: =IF(N(30)=0,"",C15/30) -> 25.661333 | V15: =IF(N(30)=0,"",I15/30) -> 1.3333333 | W15: =IF(N(H15)=0,"",L15/H15) -> -1.1979573 | X15: 417.26 | Y15: 992.06 | Z15: 20 | AA15: 683 | AB15: 52419 | AC15: 2715.7 | AD15: 57 | AE15: 57 | AF15: 2160 | AG15: -463.88 | AH15: =IF(N(Y15)=0,"",X15/Y15) -> 0.42059956 | AI15: =IF(N(AC15)=0,"",X15/AC15) -> 0.15364731 | AJ15: =IF(N(X15)=0,"",Y15/X15) -> 2.3775584 | AK15: =IF(N(AA15)=0,"",X15/AA15) -> 0.6109224 | AL15: =IF(N(AB15)=0,"",AA15/AB15) -> 0.013029627 | AM15: =IF(N(AA15)=0,"",Z15/AA15) -> 0.029282577 | AN15: =IF(N(AE15)=0,"",Z15/AE15) -> 0.35087719 | AO15: =IF(N(AD15)=0,"",AC15/AD15) -> 47.64386 | AP15: =IF(N(26)=0,"",X15/26) -> 16.048462 | AQ15: =IF(N(26)=0,"",AD15/26) -> 2.1923077 | AR15: =IF(N(AC15)=0,"",AG15/AC15) -> -0.17081415 | AS15: =IF(OR(U15="",AP15=""),"",IF(N(U15)=0,"",AP15/U15-1)) -> -0.37460531 | AT15: =IF(N(D15)=0,"",(Y15/26)/(D15/30)-1) -> -0.21350761 | AU15: =IF(OR(V15="",AQ15=""),"",IF(N(V15)=0,"",AQ15/V15-1)) -> 0.64423077 | AV15: =IF(OR(M15="",AH15=""),"",AH15-M15) -> -0.10834378 | AW15: =IF(OR(N15="",AI15=""),"",AI15-N15) -> -0.22076117 | AX15: =IF(OR(P15="",AK15=""),"",IF(N(P15)=0,"",AK15/P15-1)) -> 0.26257085 | AY15: =IF(OR(R15="",AM15=""),"",AM15-R15) -> 0.014197725 | AZ15: =IF(OR(T15="",AO15=""),"",IF(N(T15)=0,"",AO15/T15-1)) -> -0.073144281
A16: SPU07104 | B16: 车载逆变器-300W（米沃奇） | C16: 440.67 | D16: 1074.28 | E16: 28 | F16: 880 | G16: 124457 | H16: 2381.9 | I16: 89 | J16: 83 | K16: 1850 | L16: -539.49 | M16: =IF(N(D16)=0,"",C16/D16) -> 0.41020032 | N16: =IF(N(H16)=0,"",C16/H16) -> 0.18500777 | O16: =IF(N(C16)=0,"",D16/C16) -> 2.4378333 | P16: =IF(N(F16)=0,"",C16/F16) -> 0.50076136 | Q16: =IF(N(G16)=0,"",F16/G16) -> 0.0070707152 | R16: =IF(N(F16)=0,"",E16/F16) -> 0.031818182 | S16: =IF(N(J16)=0,"",E16/J16) -> 0.3373494 | T16: =IF(N(I16)=0,"",H16/I16) -> 26.762921 | U16: =IF(N(30)=0,"",C16/30) -> 14.689 | V16: =IF(N(30)=0,"",I16/30) -> 2.9666667 | W16: =IF(N(H16)=0,"",L16/H16) -> -0.22649565 | X16: 272.6 | Y16: 854.67 | Z16: 21 | AA16: 472 | AB16: 65425 | AC16: 1917.4 | AD16: 81 | AE16: 75 | AF16: 1322 | AG16: -286.45 | AH16: =IF(N(Y16)=0,"",X16/Y16) -> 0.31895351 | AI16: =IF(N(AC16)=0,"",X16/AC16) -> 0.14217169 | AJ16: =IF(N(X16)=0,"",Y16/X16) -> 3.1352531 | AK16: =IF(N(AA16)=0,"",X16/AA16) -> 0.57754237 | AL16: =IF(N(AB16)=0,"",AA16/AB16) -> 0.0072143676 | AM16: =IF(N(AA16)=0,"",Z16/AA16) -> 0.044491525 | AN16: =IF(N(AE16)=0,"",Z16/AE16) -> 0.28 | AO16: =IF(N(AD16)=0,"",AC16/AD16) -> 23.671605 | AP16: =IF(N(26)=0,"",X16/26) -> 10.484615 | AQ16: =IF(N(26)=0,"",AD16/26) -> 3.1153846 | AR16: =IF(N(AC16)=0,"",AG16/AC16) -> -0.14939501 | AS16: =IF(OR(U16="",AP16=""),"",IF(N(U16)=0,"",AP16/U16-1)) -> -0.28622674 | AT16: =IF(N(D16)=0,"",(Y16/26)/(D16/30)-1) -> -0.08202918 | AU16: =IF(OR(V16="",AQ16=""),"",IF(N(V16)=0,"",AQ16/V16-1)) -> 0.050129646 | AV16: =IF(OR(M16="",AH16=""),"",AH16-M16) -> -0.091246806 | AW16: =IF(OR(N16="",AI16=""),"",AI16-N16) -> -0.042836076 | AX16: =IF(OR(P16="",AK16=""),"",IF(N(P16)=0,"",AK16/P16-1)) -> 0.15332854 | AY16: =IF(OR(R16="",AM16=""),"",AM16-R16) -> 0.012673344 | AZ16: =IF(OR(T16="",AO16=""),"",IF(N(T16)=0,"",AO16/T16-1)) -> -0.11550744
... A20: SPU070117 | B20: 车载逆变器-300W（牧田） | C20: 0 | D20: 0 | E20: 0 | F20: 0 | G20: 0 | H20: 0 | I20: 0 | J20: 0 | K20: 78 | L20: 11.93 | M20: =IF(N(D20)=0,"",C20/D20) | N20: =IF(N(H20)=0,"",C20/H20) | O20: =IF(N(C20)=0,"",D20/C20) | P20: =IF(N(F20)=0,"",C20/F20) | Q20: =IF(N(G20)=0,"",F20/G20) | R20: =IF(N(F20)=0,"",E20/F20) | S20: =IF(N(J20)=0,"",E20/J20) | T20: =IF(N(I20)=0,"",H20/I20) | U20: =IF(N(30)=0,"",C20/30) -> 0 | V20: =IF(N(30)=0,"",I20/30) -> 0 | W20: =IF(N(H20)=0,"",L20/H20) | X20: 0 | Y20: 0 | Z20: 0 | AA20: 0 | AB20: 0 | AC20: 0 | AD20: 0 | AE20: 0 | AF20: 0 | AG20: -12.04 | AH20: =IF(N(Y20)=0,"",X20/Y20) | AI20: =IF(N(AC20)=0,"",X20/AC20) | AJ20: =IF(N(X20)=0,"",Y20/X20) | AK20: =IF(N(AA20)=0,"",X20/AA20) | AL20: =IF(N(AB20)=0,"",AA20/AB20) | AM20: =IF(N(AA20)=0,"",Z20/AA20) | AN20: =IF(N(AE20)=0,"",Z20/AE20) | AO20: =IF(N(AD20)=0,"",AC20/AD20) | AP20: =IF(N(26)=0,"",X20/26) -> 0 | AQ20: =IF(N(26)=0,"",AD20/26) -> 0 | AR20: =IF(N(AC20)=0,"",AG20/AC20) | AS20: =IF(OR(U20="",AP20=""),"",IF(N(U20)=0,"",AP20/U20-1)) | AT20: =IF(N(D20)=0,"",(Y20/26)/(D20/30)-1) | AU20: =IF(OR(V20="",AQ20=""),"",IF(N(V20)=0,"",AQ20/V20-1)) | AV20: =IF(OR(M20="",AH20=""),"",AH20-M20) | AW20: =IF(OR(N20="",AI20=""),"",AI20-N20) | AX20: =IF(OR(P20="",AK20=""),"",IF(N(P20)=0,"",AK20/P20-1)) | AY20: =IF(OR(R20="",AM20=""),"",AM20-R20) | AZ20: =IF(OR(T20="",AO20=""),"",IF(N(T20)=0,"",AO20/T20-1))
A21: 品类合计/均值 | C21: =SUM(C5:C20) -> 34165.36 | D21: =SUM(D5:D20) -> 80180.77 | E21: =SUM(E5:E20) -> 2153 | F21: =SUM(F5:F20) -> 45337 | G21: =SUM(G5:G20) -> 6129290 | H21: =SUM(H5:H20) -> 213471.15 | I21: =SUM(I5:I20) -> 6064 | J21: =SUM(J5:J20) -> 5584 | ... L21: =SUM(L5:L20) -> -25524.08 | M21: =IF(N(D21)=0,"",C21/D21) -> 0.42610416 | N21: =IF(N(H21)=0,"",C21/H21) -> 0.16004673 | O21: =IF(N(C21)=0,"",D21/C21) -> 2.346844 | P21: =IF(N(F21)=0,"",C21/F21) -> 0.7535867 | Q21: =IF(N(G21)=0,"",F21/G21) -> 0.0073967784 | R21: =IF(N(F21)=0,"",E21/F21) -> 0.047488806 | S21: =IF(N(J21)=0,"",E21/J21) -> 0.3855659 | T21: =IF(N(I21)=0,"",H21/I21) -> 35.203026 | U21: =IF(N(30)=0,"",C21/30) -> 1138.8453 | V21: =IF(N(30)=0,"",I21/30) -> 202.13333 | W21: =IF(N(H21)=0,"",L21/H21) -> -0.11956688 | X21: =SUM(X5:X20) -> 32021.91 | Y21: =SUM(Y5:Y20) -> 83159.75 | Z21: =SUM(Z5:Z20) -> 2458 | AA21: =SUM(AA5:AA20) -> 42707 | AB21: =SUM(AB5:AB20) -> 5591316 | AC21: =SUM(AC5:AC20) -> 251392.03 | AD21: =SUM(AD5:AD20) -> 7595 | AE21: =SUM(AE5:AE20) -> 6875 | ... AG21: =SUM(AG5:AG20) -> 4077.36 | AH21: =IF(N(Y21)=0,"",X21/Y21) -> 0.38506501 | AI21: =IF(N(AC21)=0,"",X21/AC21) -> 0.12737838 | AJ21: =IF(N(X21)=0,"",Y21/X21) -> 2.5969641 | AK21: =IF(N(AA21)=0,"",X21/AA21) -> 0.74980472 | AL21: =IF(N(AB21)=0,"",AA21/AB21) -> 0.0076380945 | AM21: =IF(N(AA21)=0,"",Z21/AA21) -> 0.057554968 | AN21: =IF(N(AE21)=0,"",Z21/AE21) -> 0.35752727 | AO21: =IF(N(AD21)=0,"",AC21/AD21) -> 33.099675 | AP21: =IF(N(26)=0,"",X21/26) -> 1231.6119 | AQ21: =IF(N(26)=0,"",AD21/26) -> 292.11538 | AR21: =IF(N(AC21)=0,"",AG21/AC21) -> 0.01621913 | AS21: =IF(OR(U21="",AP21=""),"",IF(N(U21)=0,"",AP21/U21-1)) -> 0.081456706 | AT21: =IF(N(D21)=0,"",(Y21/26)/(D21/30)-1) -> 0.19671534 | AU21: =IF(OR(V21="",AQ21=""),"",IF(N(V21)=0,"",AQ21/V21-1)) -> 0.44516186 | AV21: =IF(OR(M21="",AH21=""),"",AH21-M21) -> -0.041039154 | AW21: =IF(OR(N21="",AI21=""),"",AI21-N21) -> -0.03266835 | AX21: =IF(OR(P21="",AK21=""),"",IF(N(P21)=0,"",AK21/P21-1)) -> -0.0050186387 | AY21: =IF(OR(R21="",AM21=""),"",AM21-R21) -> 0.010066162 | AZ21: =IF(OR(T21="",AO21=""),"",IF(N(T21)=0,"",AO21/T21-1)) -> -0.059749161
A23: 高亮规则：红=ACOS/TACOS 超阈值、毛利为负、日均花费暴涨、ACOS 恶化；黄=CPC 偏高、广告CVR 偏低、价格变动超阈值、日均销量下滑≥20%；绿=ACOS 改善。阈值见「总览」。结算毛利润受回款结算时点影响，单月波动大，仅作参考。

Sheet ASIN月度汇总
A1: ASIN 维度 · 9月 vs 10月 广告与销售汇总（按两月广告花费降序）
A3: ASIN | B3: SPU | C3: 型号 | D3: 主要店铺 | E3: 2026年9月（30天） | Z3: 2026年10月（26天） | AU3: 10月 vs 9月
E4: 广告花费 | F4: 广告销售额 | G4: 广告订单量 | H4: 点击 | I4: 展示 | J4: 销售额 | K4: 销量 | L4: 订单量 | M4: Sessions-Total | N4: 结算毛利润 | O4: ACOS | P4: TACOS | Q4: ROAS | R4: CPC | S4: CTR | T4: 广告CVR | U4: 广告单占比 | V4: 成交均价 | W4: 日均花费 | X4: 日均销量 | Y4: 毛利率 | Z4: 广告花费 | AA4: 广告销售额 | AB4: 广告订单量 | AC4: 点击 | AD4: 展示 | AE4: 销售额 | AF4: 销量 | AG4: 订单量 | AH4: Sessions-Total | AI4: 结算毛利润 | AJ4: ACOS | AK4: TACOS | AL4: ROAS | AM4: CPC | AN4: CTR | AO4: 广告CVR | AP4: 广告单占比 | AQ4: 成交均价 | AR4: 日均花费 | AS4: 日均销量 | AT4: 毛利率 | AU4: 日均花费环比 | AV4: 广告销售额日均环比 | AW4: 日均销量环比 | AX4: ACOS变化(pp) | AY4: TACOS变化(pp) | AZ4: CPC环比 | BA4: 广告CVR变化(pp) | BB4: 成交均价环比
A5: B0CQ4Q6WB9 | B5: SPU07021 | C5: 得伟-电源逆变器-200W | D5: AMZ5-US/HK5-US/HK5-MX/HK5-CA | E5: 3423.07 | F5: 7766.49 | G5: 283 | H5: 3529 | I5: 597060 | J5: 27952.33 | K5: 1230 | L5: 1101 | M5: 39828 | N5: -2342.3 | O5: =IF(N(F5)=0,"",E5/F5) -> 0.44074865 | P5: =IF(N(J5)=0,"",E5/J5) -> 0.12246099 | Q5: =IF(N(E5)=0,"",F5/E5) -> 2.2688668 | R5: =IF(N(H5)=0,"",E5/H5) -> 0.969983 | S5: =IF(N(I5)=0,"",H5/I5) -> 0.0059106287 | T5: =IF(N(H5)=0,"",G5/H5) -> 0.080192689 | U5: =IF(N(L5)=0,"",G5/L5) -> 0.25703906 | V5: =IF(N(K5)=0,"",J5/K5) -> 22.725472 | W5: =IF(N(30)=0,"",E5/30) -> 114.10233 | X5: =IF(N(30)=0,"",K5/30) -> 41 | Y5: =IF(N(J5)=0,"",N5/J5) -> -0.083796235 | Z5: 4170.25 | AA5: 15523.62 | AB5: 554 | AC5: 6136 | AD5: 736643 | AE5: 40461.89 | AF5: 1865 | AG5: 1589 | AH5: 46587 | AI5: -373.97 | AJ5: =IF(N(AA5)=0,"",Z5/AA5) -> 0.26863902 | AK5: =IF(N(AE5)=0,"",Z5/AE5) -> 0.10306612 | AL5: =IF(N(Z5)=0,"",AA5/Z5) -> 3.7224675 | AM5: =IF(N(AC5)=0,"",Z5/AC5) -> 0.67963657 | AN5: =IF(N(AD5)=0,"",AC5/AD5) -> 0.0083296794 | AO5: =IF(N(AC5)=0,"",AB5/AC5) -> 0.090286832 | AP5: =IF(N(AG5)=0,"",AB5/AG5) -> 0.34864695 | AQ5: =IF(N(AF5)=0,"",AE5/AF5) -> 21.695383 | AR5: =IF(N(26)=0,"",Z5/26) -> 160.39423 | AS5: =IF(N(26)=0,"",AF5/26) -> 71.730769 | AT5: =IF(N(AE5)=0,"",AI5/AE5) -> -0.0092425243 | AU5: =IF(OR(W5="",AR5=""),"",IF(N(W5)=0,"",AR5/W5-1)) -> 0.40570509 | AV5: =IF(N(F5)=0,"",(AA5/26)/(F5/30)-1) -> 1.3063017 | AW5: =IF(OR(X5="",AS5=""),"",IF(N(X5)=0,"",AS5/X5-1)) -> 0.74953096 | AX5: =IF(OR(O5="",AJ5=""),"",AJ5-O5) -> -0.17210964 | AY5: =IF(OR(P5="",AK5=""),"",AK5-P5) -> -0.01939487 | AZ5: =IF(OR(R5="",AM5=""),"",IF(N(R5)=0,"",AM5/R5-1)) -> -0.29933146 | BA5: =IF(OR(T5="",AO5=""),"",AO5-T5) -> 0.010094143 | BB5: =IF(OR(V5="",AQ5=""),"",IF(N(V5)=0,"",AQ5/V5-1)) -> -0.045327472
A6: B0CQ2JJ51T | B6: SPU07022 | C6: 米沃奇-电源逆变器-200W | D6: AMZ8-CA/HK8-US/AMZ8-US/HK8-MX | E6: 2645.07 | F6: 5480.6 | G6: 176 | H6: 3876 | I6: 581971 | J6: 10895.86 | K6: 380 | L6: 368 | M6: 13375 | N6: -692.36 | O6: =IF(N(F6)=0,"",E6/F6) -> 0.48262417 | P6: =IF(N(J6)=0,"",E6/J6) -> 0.24275918 | Q6: =IF(N(E6)=0,"",F6/E6) -> 2.0720057 | R6: =IF(N(H6)=0,"",E6/H6) -> 0.6824226 | S6: =IF(N(I6)=0,"",H6/I6) -> 0.0066601257 | T6: =IF(N(H6)=0,"",G6/H6) -> 0.045407637 | U6: =IF(N(L6)=0,"",G6/L6) -> 0.47826087 | V6: =IF(N(K6)=0,"",J6/K6) -> 28.673316 | W6: =IF(N(30)=0,"",E6/30) -> 88.169 | X6: =IF(N(30)=0,"",K6/30) -> 12.666667 | Y6: =IF(N(J6)=0,"",N6/J6) -> -0.063543401 | Z6: 3852.8 | AA6: 7091.49 | AB6: 231 | AC6: 4937 | AD6: 681001 | AE6: 14001.04 | AF6: 500 | AG6: 472 | AH6: 18880 | AI6: -1910.08 | AJ6: =IF(N(AA6)=0,"",Z6/AA6) -> 0.54329908 | AK6: =IF(N(AE6)=0,"",Z6/AE6) -> 0.27517956 | AL6: =IF(N(Z6)=0,"",AA6/Z6) -> 1.8406068 | AM6: =IF(N(AC6)=0,"",Z6/AC6) -> 0.78039295 | AN6: =IF(N(AD6)=0,"",AC6/AD6) -> 0.0072496222 | AO6: =IF(N(AC6)=0,"",AB6/AC6) -> 0.046789548 | AP6: =IF(N(AG6)=0,"",AB6/AG6) -> 0.48940678 | AQ6: =IF(N(AF6)=0,"",AE6/AF6) -> 28.00208 | AR6: =IF(N(26)=0,"",Z6/26) -> 148.18462 | AS6: =IF(N(26)=0,"",AF6/26) -> 19.230769 | AT6: =IF(N(AE6)=0,"",AI6/AE6) -> -0.13642415 | AU6: =IF(OR(W6="",AR6=""),"",IF(N(W6)=0,"",AR6/W6-1)) -> 0.6806884 | AV6: =IF(N(F6)=0,"",(AA6/26)/(F6/30)-1) -> 0.49299136 | AW6: =IF(OR(X6="",AS6=""),"",IF(N(X6)=0,"",AS6/X6-1)) -> 0.51821862 | AX6: =IF(OR(O6="",AJ6=""),"",AJ6-O6) -> 0.060674916 | AY6: =IF(OR(P6="",AK6=""),"",AK6-P6) -> 0.032420382 | AZ6: =IF(OR(R6="",AM6=""),"",IF(N(R6)=0,"",AM6/R6-1)) -> 0.14356258 | BA6: =IF(OR(T6="",AO6=""),"",AO6-T6) -> 0.0013819116 | BB6: =IF(OR(V6="",AQ6=""),"",IF(N(V6)=0,"",AQ6/V6-1)) -> -0.023409772
A7: B0CQ4PFGH5 | B7: SPU07022 | C7: 米沃奇-电源逆变器-200W | D7: AMZ5-US/HK5-US | E7: 2584.13 | F7: 5555.8 | G7: 222 | H7: 2453 | I7: 561693 | J7: 13831.65 | K7: 618 | L7: 560 | M7: 16296 | N7: 71.18 | O7: =IF(N(F7)=0,"",E7/F7) -> 0.46512293 | P7: =IF(N(J7)=0,"",E7/J7) -> 0.18682731 | Q7: =IF(N(E7)=0,"",F7/E7) -> 2.1499692 | R7: =IF(N(H7)=0,"",E7/H7) -> 1.053457 | S7: =IF(N(I7)=0,"",H7/I7) -> 0.0043671543 | T7: =IF(N(H7)=0,"",G7/H7) -> 0.090501427 | U7: =IF(N(L7)=0,"",G7/L7) -> 0.39642857 | V7: =IF(N(K7)=0,"",J7/K7) -> 22.381311 | W7: =IF(N(30)=0,"",E7/30) -> 86.137667 | X7: =IF(N(30)=0,"",K7/30) -> 20.6 | Y7: =IF(N(J7)=0,"",N7/J7) -> 0.0051461684 | Z7: 3709 | AA7: 8919.81 | AB7: 353 | AC7: 5343 | AD7: 1096274 | AE7: 18597.48 | AF7: 856 | AG7: 760 | AH7: 20832 | AI7: -1758.54 | AJ7: =IF(N(AA7)=0,"",Z7/AA7) -> 0.41581603 | AK7: =IF(N(AE7)=0,"",Z7/AE7) -> 0.19943562 | AL7: =IF(N(Z7)=0,"",AA7/Z7) -> 2.4049097 | AM7: =IF(N(AC7)=0,"",Z7/AC7) -> 0.6941793 | AN7: =IF(N(AD7)=0,"",AC7/AD7) -> 0.0048737816 | AO7: =IF(N(AC7)=0,"",AB7/AC7) -> 0.066067752 | AP7: =IF(N(AG7)=0,"",AB7/AG7) -> 0.46447368 | AQ7: =IF(N(AF7)=0,"",AE7/AF7) -> 21.726028 | AR7: =IF(N(26)=0,"",Z7/26) -> 142.65385 | AS7: =IF(N(26)=0,"",AF7/26) -> 32.923077 | AT7: =IF(N(AE7)=0,"",AI7/AE7) -> -0.094557972 | AU7: =IF(OR(W7="",AR7=""),"",IF(N(W7)=0,"",AR7/W7-1)) -> 0.65611459 | AV7: =IF(N(F7)=0,"",(AA7/26)/(F7/30)-1) -> 0.85249441 | AW7: =IF(OR(X7="",AS7=""),"",IF(N(X7)=0,"",AS7/X7-1)) -> 0.59820762 | AX7: =IF(OR(O7="",AJ7=""),"",AJ7-O7) -> -0.049306903 | AY7: =IF(OR(P7="",AK7=""),"",AK7-P7) -> 0.01260831 | AZ7: =IF(OR(R7="",AM7=""),"",IF(N(R7)=0,"",AM7/R7-1)) -> -0.34104638 | BA7: =IF(OR(T7="",AO7=""),"",AO7-T7) -> -0.024433675 | BB7: =IF(OR(V7="",AQ7=""),"",IF(N(V7)=0,"",AQ7/V7-1)) -> -0.029278117
A8: B0CQ2MHKJ5 | B8: SPU07021 | C8: 得伟-电源逆变器-200W | D8: HK8-US/AMZ8-US/AMZ8-CA/HK8-CA | E8: 1808.4 | F8: 3416.67 | G8: 103 | H8: 1107 | I8: 285328 | J8: 10213.97 | K8: 356 | L8: 319 | M8: 9847 | N8: 455.48 | O8: =IF(N(F8)=0,"",E8/F8) -> 0.52928729 | P8: =IF(N(J8)=0,"",E8/J8) -> 0.17705163 | Q8: =IF(N(E8)=0,"",F8/E8) -> 1.8893331 | R8: =IF(N(H8)=0,"",E8/H8) -> 1.6336043 | S8: =IF(N(I8)=0,"",H8/I8) -> 0.0038797454 | T8: =IF(N(H8)=0,"",G8/H8) -> 0.093044264 | U8: =IF(N(L8)=0,"",G8/L8) -> 0.32288401 | V8: =IF(N(K8)=0,"",J8/K8) -> 28.690927 | W8: =IF(N(30)=0,"",E8/30) -> 60.28 | X8: =IF(N(30)=0,"",K8/30) -> 11.866667 | Y8: =IF(N(J8)=0,"",N8/J8) -> 0.044593826 | Z8: 4484.7 | AA8: 14286.01 | AB8: 418 | AC8: 4163 | AD8: 512713 | AE8: 25577.47 | AF8: 891 | AG8: 843 | AH8: 23302 | AI8: -1217.16 | AJ8: =IF(N(AA8)=0,"",Z8/AA8) -> 0.3139225 | AK8: =IF(N(AE8)=0,"",Z8/AE8) -> 0.1753379 | AL8: =IF(N(Z8)=0,"",AA8/Z8) -> 3.1854996 | AM8: =IF(N(AC8)=0,"",Z8/AC8) -> 1.077276 | AN8: =IF(N(AD8)=0,"",AC8/AD8) -> 0.0081195523 | AO8: =IF(N(AC8)=0,"",AB8/AC8) -> 0.10040836 | AP8: =IF(N(AG8)=0,"",AB8/AG8) -> 0.49584816 | AQ8: =IF(N(AF8)=0,"",AE8/AF8) -> 28.706476 | AR8: =IF(N(26)=0,"",Z8/26) -> 172.48846 | AS8: =IF(N(26)=0,"",AF8/26) -> 34.269231 | AT8: =IF(N(AE8)=0,"",AI8/AE8) -> -0.047587193 | AU8: =IF(OR(W8="",AR8=""),"",IF(N(W8)=0,"",AR8/W8-1)) -> 1.8614542 | AV8: =IF(N(F8)=0,"",(AA8/26)/(F8/30)-1) -> 3.824539 | AW8: =IF(OR(X8="",AS8=""),"",IF(N(X8)=0,"",AS8/X8-1)) -> 1.8878565 | AX8: =IF(OR(O8="",AJ8=""),"",AJ8-O8) -> -0.21536479 | AY8: =IF(OR(P8="",AK8=""),"",AK8-P8) -> -0.0017137215 | AZ8: =IF(OR(R8="",AM8=""),"",IF(N(R8)=0,"",AM8/R8-1)) -> -0.34055268 | BA8: =IF(OR(T8="",AO8=""),"",AO8-T8) -> 0.0073640956 | BB8: =IF(OR(V8="",AQ8=""),"",IF(N(V8)=0,"",AQ8/V8-1)) -> 0.00054194497
A9: B0DQKKF484 | B9: SPU07060 | C9: 利优比-电源逆变器-200W | D9: AMZ5-US/HK5-US | E9: 2474.49 | F9: 6782.43 | G9: 186 | H9: 5519 | I9: 739233 | J9: 8881.15 | K9: 256 | L9: 246 | M9: 11827 | N9: -6698.67 | O9: =IF(N(F9)=0,"",E9/F9) -> 0.36483827 | P9: =IF(N(J9)=0,"",E9/J9) -> 0.2786227 | Q9: =IF(N(E9)=0,"",F9/E9) -> 2.7409406 | R9: =IF(N(H9)=0,"",E9/H9) -> 0.4483584 | S9: =IF(N(I9)=0,"",H9/I9) -> 0.0074658464 | T9: =IF(N(H9)=0,"",G9/H9) -> 0.033701758 | U9: =IF(N(L9)=0,"",G9/L9) -> 0.75609756 | V9: =IF(N(K9)=0,"",J9/K9) -> 34.691992 | W9: =IF(N(30)=0,"",E9/30) -> 82.483 | X9: =IF(N(30)=0,"",K9/30) -> 8.5333333 | Y9: =IF(N(J9)=0,"",N9/J9) -> -0.75425705 | Z9: 1577.74 | AA9: 3183.98 | AB9: 79 | AC9: 3414 | AD9: 261524 | AE9: 5633.42 | AF9: 168 | AG9: 165 | AH9: 12544 | AI9: 498.91 | AJ9: =IF(N(AA9)=0,"",Z9/AA9) -> 0.49552447 | AK9: =IF(N(AE9)=0,"",Z9/AE9) -> 0.28006788 | AL9: =IF(N(Z9)=0,"",AA9/Z9) -> 2.0180638 | AM9: =IF(N(AC9)=0,"",Z9/AC9) -> 0.46213825 | AN9: =IF(N(AD9)=0,"",AC9/AD9) -> 0.013054251 | AO9: =IF(N(AC9)=0,"",AB9/AC9) -> 0.023140012 | AP9: =IF(N(AG9)=0,"",AB9/AG9) -> 0.47878788 | AQ9: =IF(N(AF9)=0,"",AE9/AF9) -> 33.532262 | AR9: =IF(N(26)=0,"",Z9/26) -> 60.682308 | AS9: =IF(N(26)=0,"",AF9/26) -> 6.4615385 | AT9: =IF(N(AE9)=0,"",AI9/AE9) -> 0.088562543 | AU9: =IF(OR(W9="",AR9=""),"",IF(N(W9)=0,"",AR9/W9-1)) -> -0.26430528 | AV9: =IF(N(F9)=0,"",(AA9/26)/(F9/30)-1) -> -0.45833233 | AW9: =IF(OR(X9="",AS9=""),"",IF(N(X9)=0,"",AS9/X9-1)) -> -0.24278846 | AX9: =IF(OR(O9="",AJ9=""),"",AJ9-O9) -> 0.1306862 | AY9: =IF(OR(P9="",AK9=""),"",AK9-P9) -> 0.0014451797 | AZ9: =IF(OR(R9="",AM9=""),"",IF(N(R9)=0,"",AM9/R9-1)) -> 0.03073402 | BA9: =IF(OR(T9="",AO9=""),"",AO9-T9) -> -0.010561746 | BB9: =IF(OR(V9="",AQ9=""),"",IF(N(V9)=0,"",AQ9/V9-1)) -> -0.033429337
A10: B0GXJ3VN4S | B10: SPU50039 | C10: 得伟-单包逆变器350W-修正波版-美规-黄色 | D10: AMZ5-US/HK5-US | E10: 2514.02 | F10: 6333.13 | G10: 150 | H10: 2486 | I10: 296639 | J10: 12555.05 | K10: 311 | L10: 293 | M10: 8253 | N10: -689.7 | O10: =IF(N(F10)=0,"",E10/F10) -> 0.39696327 | P10: =IF(N(J10)=0,"",E10/J10) -> 0.20023974 | Q10: =IF(N(E10)=0,"",F10/E10) -> 2.5191247 | R10: =IF(N(H10)=0,"",E10/H10) -> 1.0112711 | S10: =IF(N(I10)=0,"",H10/I10) -> 0.0083805568 | T10: =IF(N(H10)=0,"",G10/H10) -> 0.060337892 | U10: =IF(N(L10)=0,"",G10/L10) -> 0.51194539 | V10: =IF(N(K10)=0,"",J10/K10) -> 40.369936 | W10: =IF(N(30)=0,"",E10/30) -> 83.800667 | X10: =IF(N(30)=0,"",K10/30) -> 10.366667 | Y10: =IF(N(J10)=0,"",N10/J10) -> -0.05493407 | Z10: 1411.24 | AA10: 3744.5 | AB10: 89 | AC10: 1518 | AD10: 175574 | AE10: 6394.24 | AF10: 157 | AG10: 143 | AH10: 6662 | AI10: -277.48 | AJ10: =IF(N(AA10)=0,"",Z10/AA10) -> 0.37688343 | AK10: =IF(N(AE10)=0,"",Z10/AE10) -> 0.22070488 | AL10: =IF(N(Z10)=0,"",AA10/Z10) -> 2.6533403 | AM10: =IF(N(AC10)=0,"",Z10/AC10) -> 0.92967062 | AN10: =IF(N(AD10)=0,"",AC10/AD10) -> 0.0086459271 | AO10: =IF(N(AC10)=0,"",AB10/AC10) -> 0.058629776 | AP10: =IF(N(AG10)=0,"",AB10/AG10) -> 0.62237762 | AQ10: =IF(N(AF10)=0,"",AE10/AF10) -> 40.727643 | AR10: =IF(N(26)=0,"",Z10/26) -> 54.278462 | AS10: =IF(N(26)=0,"",AF10/26) -> 6.0384615 | AT10: =IF(N(AE10)=0,"",AI10/AE10) -> -0.043395306 | AU10: =IF(OR(W10="",AR10=""),"",IF(N(W10)=0,"",AR10/W10-1)) -> -0.35229081 | AV10: =IF(N(F10)=0,"",(AA10/26)/(F10/30)-1) -> -0.31778174 | AW10: =IF(OR(X10="",AS10=""),"",IF(N(X10)=0,"",AS10/X10-1)) -> -0.41751175 | AX10: =IF(OR(O10="",AJ10=""),"",AJ10-O10) -> -0.020079842 | AY10: =IF(OR(P10="",AK10=""),"",AK10-P10) -> 0.02046514 | AZ10: =IF(OR(R10="",AM10=""),"",IF(N(R10)=0,"",AM10/R10-1)) -> -0.080691021 | BA10: =IF(OR(T10="",AO10=""),"",AO10-T10) -> -0.0017081162 | BB10: =IF(OR(V10="",AQ10=""),"",IF(N(V10)=0,"",AQ10/V10-1)) -> 0.0088607429
A11: B0GXHN35JL | B11: SPU50039 | C11: 米沃奇-单包逆变器350W-修正波版-美规-红色 | D11: AMZ5-US | E11: 1799.96 | F11: 2674.04 | G11: 62 | H11: 1558 | I11: 170396 | J11: 5469.11 | K11: 139 | L11: 132 | M11: 4141 | N11: -1332.29 | O11: =IF(N(F11)=0,"",E11/F11) -> 0.67312381 | P11: =IF(N(J11)=0,"",E11/J11) -> 0.32911388 | Q11: =IF(N(E11)=0,"",F11/E11) -> 1.4856108 | R11: =IF(N(H11)=0,"",E11/H11) -> 1.1553017 | S11: =IF(N(I11)=0,"",H11/I11) -> 0.0091434071 | T11: =IF(N(H11)=0,"",G11/H11) -> 0.039794608 | U11: =IF(N(L11)=0,"",G11/L11) -> 0.46969697 | V11: =IF(N(K11)=0,"",J11/K11) -> 39.346115 | W11: =IF(N(30)=0,"",E11/30) -> 59.998667 | X11: =IF(N(30)=0,"",K11/30) -> 4.6333333 | Y11: =IF(N(J11)=0,"",N11/J11) -> -0.24360271 | Z11: 2071.66 | AA11: 2536.11 | AB11: 64 | AC11: 1894 | AD11: 201332 | AE11: 5080.73 | AF11: 127 | AG11: 127 | AH11: 3226 | AI11: -2342.14 | AJ11: =IF(N(AA11)=0,"",Z11/AA11) -> 0.8168652 | AK11: =IF(N(AE11)=0,"",Z11/AE11) -> 0.40774849 | AL11: =IF(N(Z11)=0,"",AA11/Z11) -> 1.2241922 | AM11: =IF(N(AC11)=0,"",Z11/AC11) -> 1.0938015 | AN11: =IF(N(AD11)=0,"",AC11/AD11) -> 0.0094073471 | AO11: =IF(N(AC11)=0,"",AB11/AC11) -> 0.033790919 | AP11: =IF(N(AG11)=0,"",AB11/AG11) -> 0.50393701 | AQ11: =IF(N(AF11)=0,"",AE11/AF11) -> 40.005748 | AR11: =IF(N(26)=0,"",Z11/26) -> 79.679231 | AS11: =IF(N(26)=0,"",AF11/26) -> 4.8846154 | AT11: =IF(N(AE11)=0,"",AI11/AE11) -> -0.46098494 | AU11: =IF(OR(W11="",AR11=""),"",IF(N(W11)=0,"",AR11/W11-1)) -> 0.32801669 | AV11: =IF(N(F11)=0,"",(AA11/26)/(F11/30)-1) -> 0.094329467 | AW11: =IF(OR(X11="",AS11=""),"",IF(N(X11)=0,"",AS11/X11-1)) -> 0.054233536 | AX11: =IF(OR(O11="",AJ11=""),"",AJ11-O11) -> 0.14374139 | AY11: =IF(OR(P11="",AK11=""),"",AK11-P11) -> 0.078634615 | AZ11: =IF(OR(R11="",AM11=""),"",IF(N(R11)=0,"",AM11/R11-1)) -> -0.053233014 | BA11: =IF(OR(T11="",AO11=""),"",AO11-T11) -> -0.0060036898 | BB11: =IF(OR(V11="",AQ11=""),"",IF(N(V11)=0,"",AQ11/V11-1)) -> 0.016764881
A12: B0DHZSTBSD | B12: SPU07060 | C12: 利优比-电源逆变器-200W | D12: HK8-US/AMZ8-US | E12: 1623.49 | F12: 6889.16 | G12: 178 | H12: 2245 | I12: 272913 | J12: 20654.79 | K12: 573 | L12: 560 | M12: 17204 | N12: 6947.83 | O12: =IF(N(F12)=0,"",E12/F12) -> 0.23565863 | P12: =IF(N(J12)=0,"",E12/J12) -> 0.078601138 | Q12: =IF(N(E12)=0,"",F12/E12) -> 4.2434262 | R12: =IF(N(H12)=0,"",E12/H12) -> 0.72315813 | S12: =IF(N(I12)=0,"",H12/I12) -> 0.0082260647 | T12: =IF(N(H12)=0,"",G12/H12) -> 0.079287305 | U12: =IF(N(L12)=0,"",G12/L12) -> 0.31785714 | V12: =IF(N(K12)=0,"",J12/K12) -> 36.046754 | W12: =IF(N(30)=0,"",E12/30) -> 54.116333 | X12: =IF(N(30)=0,"",K12/30) -> 19.1 | Y12: =IF(N(J12)=0,"",N12/J12) -> 0.33637863 | Z12: 475.8 | AA12: 2658.01 | AB12: 72 | AC12: 529 | AD12: 115060 | AE12: 25810.84 | AF12: 716 | AG12: 701 | AH12: 19046 | AI12: 7815.2 | AJ12: =IF(N(AA12)=0,"",Z12/AA12) -> 0.1790061 | AK12: =IF(N(AE12)=0,"",Z12/AE12) -> 0.018434115 | AL12: =IF(N(Z12)=0,"",AA12/Z12) -> 5.5864018 | AM12: =IF(N(AC12)=0,"",Z12/AC12) -> 0.89943289 | AN12: =IF(N(AD12)=0,"",AC12/AD12) -> 0.0045976013 | AO12: =IF(N(AC12)=0,"",AB12/AC12) -> 0.13610586 | AP12: =IF(N(AG12)=0,"",AB12/AG12) -> 0.10271041 | AQ12: =IF(N(AF12)=0,"",AE12/AF12) -> 36.048659 | AR12: =IF(N(26)=0,"",Z12/26) -> 18.3 | AS12: =IF(N(26)=0,"",AF12/26) -> 27.538462 | AT12: =IF(N(AE12)=0,"",AI12/AE12) -> 0.30278751 | AU12: =IF(OR(W12="",AR12=""),"",IF(N(W12)=0,"",AR12/W12-1)) -> -0.66183962 | AV12: =IF(N(F12)=0,"",(AA12/26)/(F12/30)-1) -> -0.55481733 | AW12: =IF(OR(X12="",AS12=""),"",IF(N(X12)=0,"",AS12/X12-1)) -> 0.44180427 | AX12: =IF(OR(O12="",AJ12=""),"",AJ12-O12) -> -0.05665253 | AY12: =IF(OR(P12="",AK12=""),"",AK12-P12) -> -0.060167023 | AZ12: =IF(OR(R12="",AM12=""),"",IF(N(R12)=0,"",AM12/R12-1)) -> 0.24375687 | BA12: =IF(OR(T12="",AO12=""),"",AO12-T12) -> 0.056818555 | BB12: =IF(OR(V12="",AQ12=""),"",IF(N(V12)=0,"",AQ12/V12-1)) -> 5.285611e-05
A13: B0GXJ1P8X2 | B13: SPU50039 | C13: 牧田-单包逆变器350W-修正波版-美规-蓝色 | D13: AMZ5-US/AMZ5-CA | E13: 822.37 | F13: 1329.94 | G13: 32 | H13: 985 | I13: 109415 | J13: 2765.1 | K13: 60 | L13: 59 | M13: 2374 | N13: -207.27 | O13: =IF(N(F13)=0,"",E13/F13) -> 0.6183512 | P13: =IF(N(J13)=0,"",E13/J13) -> 0.29741058 | Q13: =IF(N(E13)=0,"",F13/E13) -> 1.6172039 | R13: =IF(N(H13)=0,"",E13/H13) -> 0.8348934 | S13: =IF(N(I13)=0,"",H13/I13) -> 0.009002422 | T13: =IF(N(H13)=0,"",G13/H13) -> 0.03248731 | U13: =IF(N(L13)=0,"",G13/L13) -> 0.54237288 | V13: =IF(N(K13)=0,"",J13/K13) -> 46.085 | W13: =IF(N(30)=0,"",E13/30) -> 27.412333 | X13: =IF(N(30)=0,"",K13/30) -> 2 | Y13: =IF(N(J13)=0,"",N13/J13) -> -0.074959314 | Z13: 861.16 | AA13: 1069.49 | AB13: 25 | AC13: 1105 | AD13: 92376 | AE13: 1938.74 | AF13: 43 | AG13: 43 | AH13: 1813 | AI13: -602.47 | AJ13: =IF(N(AA13)=0,"",Z13/AA13) -> 0.80520622 | AK13: =IF(N(AE13)=0,"",Z13/AE13) -> 0.4441854 | AL13: =IF(N(Z13)=0,"",AA13/Z13) -> 1.2419179 | AM13: =IF(N(AC13)=0,"",Z13/AC13) -> 0.77933032 | AN13: =IF(N(AD13)=0,"",AC13/AD13) -> 0.011961981 | AO13: =IF(N(AC13)=0,"",AB13/AC13) -> 0.022624434 | AP13: =IF(N(AG13)=0,"",AB13/AG13) -> 0.58139535 | AQ13: =IF(N(AF13)=0,"",AE13/AF13) -> 45.086977 | AR13: =IF(N(26)=0,"",Z13/26) -> 33.121538 | AS13: =IF(N(26)=0,"",AF13/26) -> 1.6538462 | AT13: =IF(N(AE13)=0,"",AI13/AE13) -> -0.31075338 | AU13: =IF(OR(W13="",AR13=""),"",IF(N(W13)=0,"",AR13/W13-1)) -> 0.2082714 | AV13: =IF(N(F13)=0,"",(AA13/26)/(F13/30)-1) -> -0.072118349 | AW13: =IF(OR(X13="",AS13=""),"",IF(N(X13)=0,"",AS13/X13-1)) -> -0.17307692 | AX13: =IF(OR(O13="",AJ13=""),"",AJ13-O13) -> 0.18685502 | AY13: =IF(OR(P13="",AK13=""),"",AK13-P13) -> 0.14677482 | AZ13: =IF(OR(R13="",AM13=""),"",IF(N(R13)=0,"",AM13/R13-1)) -> -0.066551112 | BA13: =IF(OR(T13="",AO13=""),"",AO13-T13) -> -0.0098628753 | BB13: =IF(OR(V13="",AQ13=""),"",IF(N(V13)=0,"",AQ13/V13-1)) -> -0.021656141
A14: B0CYZYC9HX | B14: SPU07051 | C14: 牧田-电源逆变器200W | D14: AMZ5-US/HK5-US | E14: 1167.67 | F14: 2484.88 | G14: 70 | H14: 1282 | I14: 351469 | J14: 5836.23 | K14: 171 | L14: 160 | M14: 10464 | N14: 1307.65 | O14: =IF(N(F14)=0,"",E14/F14) -> 0.46991002 | P14: =IF(N(J14)=0,"",E14/J14) -> 0.20007265 | Q14: =IF(N(E14)=0,"",F14/E14) -> 2.128067 | R14: =IF(N(H14)=0,"",E14/H14) -> 0.91081903 | S14: =IF(N(I14)=0,"",H14/I14) -> 0.0036475479 | T14: =IF(N(H14)=0,"",G14/H14) -> 0.054602184 | U14: =IF(N(L14)=0,"",G14/L14) -> 0.4375 | V14: =IF(N(K14)=0,"",J14/K14) -> 34.13 | W14: =IF(N(30)=0,"",E14/30) -> 38.922333 | X14: =IF(N(30)=0,"",K14/30) -> 5.7 | Y14: =IF(N(J14)=0,"",N14/J14) -> 0.22405731 | Z14: 441.33 | AA14: 989.24 | AB14: 30 | AC14: 540 | AD14: 250071 | AE14: 4471.63 | AF14: 137 | AG14: 125 | AH14: 7600 | AI14: 1108.21 | AJ14: =IF(N(AA14)=0,"",Z14/AA14) -> 0.44613036 | AK14: =IF(N(AE14)=0,"",Z14/AE14) -> 0.098695554 | AL14: =IF(N(Z14)=0,"",AA14/Z14) -> 2.2414973 | AM14: =IF(N(AC14)=0,"",Z14/AC14) -> 0.81727778 | AN14: =IF(N(AD14)=0,"",AC14/AD14) -> 0.0021593867 | AO14: =IF(N(AC14)=0,"",AB14/AC14) -> 0.055555556 | AP14: =IF(N(AG14)=0,"",AB14/AG14) -> 0.24 | AQ14: =IF(N(AF14)=0,"",AE14/AF14) -> 32.639635 | AR14: =IF(N(26)=0,"",Z14/26) -> 16.974231 | AS14: =IF(N(26)=0,"",AF14/26) -> 5.2692308 | AT14: =IF(N(AE14)=0,"",AI14/AE14) -> 0.24783133 | AU14: =IF(OR(W14="",AR14=""),"",IF(N(W14)=0,"",AR14/W14-1)) -> -0.56389483 | AV14: =IF(N(F14)=0,"",(AA14/26)/(F14/30)-1) -> -0.54064954 | AW14: =IF(OR(X14="",AS14=""),"",IF(N(X14)=0,"",AS14/X14-1)) -> -0.075573549 | AX14: =IF(OR(O14="",AJ14=""),"",AJ14-O14) -> -0.023779653 | AY14: =IF(OR(P14="",AK14=""),"",AK14-P14) -> -0.1013771 | AZ14: =IF(OR(R14="",AM14=""),"",IF(N(R14)=0,"",AM14/R14-1)) -> -0.10270015 | BA14: =IF(OR(T14="",AO14=""),"",AO14-T14) -> 0.00095337147 | BB14: =IF(OR(V14="",AQ14=""),"",IF(N(V14)=0,"",AQ14/V14-1)) -> -0.0436673
A15: B0CYZVRNJ7 | B15: SPU07051 | C15: 牧田-电源逆变器200W | D15: AMZ8-US/HK8-CA/AMZ8-MX | E15: 832.23 | F15: 2017.21 | G15: 51 | H15: 1625 | I15: 127172 | J15: 4887.12 | K15: 148 | L15: 119 | M15: 2944 | N15: 497.82 | O15: =IF(N(F15)=0,"",E15/F15) -> 0.41256488 | P15: =IF(N(J15)=0,"",E15/J15) -> 0.17029048 | Q15: =IF(N(E15)=0,"",F15/E15) -> 2.4238612 | R15: =IF(N(H15)=0,"",E15/H15) -> 0.51214154 | S15: =IF(N(I15)=0,"",H15/I15) -> 0.01277797 | T15: =IF(N(H15)=0,"",G15/H15) -> 0.031384615 | U15: =IF(N(L15)=0,"",G15/L15) -> 0.42857143 | V15: =IF(N(K15)=0,"",J15/K15) -> 33.021081 | W15: =IF(N(30)=0,"",E15/30) -> 27.741 | X15: =IF(N(30)=0,"",K15/30) -> 4.9333333 | Y15: =IF(N(J15)=0,"",N15/J15) -> 0.10186367 | Z15: 765.76 | AA15: 2111.22 | AB15: 57 | AC15: 1499 | AD15: 133845 | AE15: 2841.41 | AF15: 79 | AG15: 78 | AH15: 2957 | AI15: 221.23 | AJ15: =IF(N(AA15)=0,"",Z15/AA15) -> 0.36270971 | AK15: =IF(N(AE15)=0,"",Z15/AE15) -> 0.2695 | AL15: =IF(N(Z15)=0,"",AA15/Z15) -> 2.7570257 | AM15: =IF(N(AC15)=0,"",Z15/AC15) -> 0.51084723 | AN15: =IF(N(AD15)=0,"",AC15/AD15) -> 0.011199522 | AO15: =IF(N(AC15)=0,"",AB15/AC15) -> 0.03802535 | AP15: =IF(N(AG15)=0,"",AB15/AG15) -> 0.73076923 | AQ15: =IF(N(AF15)=0,"",AE15/AF15) -> 35.967215 | AR15: =IF(N(26)=0,"",Z15/26) -> 29.452308 | AS15: =IF(N(26)=0,"",AF15/26) -> 3.0384615 | AT15: =IF(N(AE15)=0,"",AI15/AE15) -> 0.077859232 | AU15: =IF(OR(W15="",AR15=""),"",IF(N(W15)=0,"",AR15/W15-1)) -> 0.061688753 | AV15: =IF(N(F15)=0,"",(AA15/26)/(F15/30)-1) -> 0.20761997 | AW15: =IF(OR(X15="",AS15=""),"",IF(N(X15)=0,"",AS15/X15-1)) -> -0.38409563 | AX15: =IF(OR(O15="",AJ15=""),"",AJ15-O15) -> -0.049855166 | AY15: =IF(OR(P15="",AK15=""),"",AK15-P15) -> 0.099209524 | AZ15: =IF(OR(R15="",AM15=""),"",IF(N(R15)=0,"",AM15/R15-1)) -> -0.0025272447 | BA15: =IF(OR(T15="",AO15=""),"",AO15-T15) -> 0.0066407348 | BB15: =IF(OR(V15="",AQ15=""),"",IF(N(V15)=0,"",AQ15/V15-1)) -> 0.089219796
A16: B0F9FQ2FVF | B16: SPU07060 | C16: 利优比-电源逆变器-200W | D16: AMZ8-US | E16: 1392.59 | F16: 2608.69 | G16: 77 | H16: 2846 | I16: 204883 | J16: 3882.92 | K16: 121 | L16: 119 | M16: 3427 | N16: -14.5 | O16: =IF(N(F16)=0,"",E16/F16) -> 0.53382732 | P16: =IF(N(J16)=0,"",E16/J16) -> 0.35864504 | Q16: =IF(N(E16)=0,"",F16/E16) -> 1.8732649 | R16: =IF(N(H16)=0,"",E16/H16) -> 0.48931483 | S16: =IF(N(I16)=0,"",H16/I16) -> 0.013890855 | T16: =IF(N(H16)=0,"",G16/H16) -> 0.027055517 | U16: =IF(N(L16)=0,"",G16/L16) -> 0.64705882 | V16: =IF(N(K16)=0,"",J16/K16) -> 32.090248 | W16: =IF(N(30)=0,"",E16/30) -> 46.419667 | X16: =IF(N(30)=0,"",K16/30) -> 4.0333333 | Y16: =IF(N(J16)=0,"",N16/J16) -> -0.0037343031 | Z16: 90.55 | AA16: 97.32 | AB16: 3 | AC16: 189 | AD16: 16730 | AE16: 65.98 | AF16: 2 | AG16: 2 | AH16: 213 | AI16: 372.89 | AJ16: =IF(N(AA16)=0,"",Z16/AA16) -> 0.93043568 | AK16: =IF(N(AE16)=0,"",Z16/AE16) -> 1.3723856 | AL16: =IF(N(Z16)=0,"",AA16/Z16) -> 1.0747653 | AM16: =IF(N(AC16)=0,"",Z16/AC16) -> 0.47910053 | AN16: =IF(N(AD16)=0,"",AC16/AD16) -> 0.011297071 | AO16: =IF(N(AC16)=0,"",AB16/AC16) -> 0.015873016 | AP16: =IF(N(AG16)=0,"",AB16/AG16) -> 1.5 | AQ16: =IF(N(AF16)=0,"",AE16/AF16) -> 32.99 | AR16: =IF(N(26)=0,"",Z16/26) -> 3.4826923 | AS16: =IF(N(26)=0,"",AF16/26) -> 0.076923077 | AT16: =IF(N(AE16)=0,"",AI16/AE16) -> 5.6515611 | AU16: =IF(OR(W16="",AR16=""),"",IF(N(W16)=0,"",AR16/W16-1)) -> -0.92497378 | AV16: =IF(N(F16)=0,"",(AA16/26)/(F16/30)-1) -> -0.95695452 | AW16: =IF(OR(X16="",AS16=""),"",IF(N(X16)=0,"",AS16/X16-1)) -> -0.98092816 | AX16: =IF(OR(O16="",AJ16=""),"",AJ16-O16) -> 0.39660835 | AY16: =IF(OR(P16="",AK16=""),"",AK16-P16) -> 1.0137405 | AZ16: =IF(OR(R16="",AM16=""),"",IF(N(R16)=0,"",AM16/R16-1)) -> -0.020874697 | BA16: =IF(OR(T16="",AO16=""),"",AO16-T16) -> -0.011182501 | BB16: =IF(OR(V16="",AQ16=""),"",IF(N(V16)=0,"",AQ16/V16-1)) -> 0.028038177
